Workbook
Name diploma: #REF!
Name diploma: #REF!
Name diploma: #REF!
Name diploma: #REF!

Sheet DAFTAR ISI
A1: NAMA SHEET | B1: KETERANGAN
A2: Isian Prodi | B2: Wajib diisi oleh semua PS
A3: Kertas Kerja | B3: Wajib diisi oleh semua PS
A4: Form Monev PT | B4: Diisi oleh Rektorat bersama Direktorat
A5: Form Monev UPPS BAN-PT | B5: Diisi oleh UPPS yang mengelola PS yang diakreditasi oleh BANPT
A6: Form Monev UPPS LAM INFOKOM | B6: Diisi oleh UPPS yang mengelola PS yang diakreditasi oleh LAM INFOKOM
A7: Form Monev UPPS LAM PTKES NERS | B7: Diisi oleh UPPS yang mengelola PS yang diakreditasi oleh LAM PTKES NERS
A8: Form Monev UPPS LAM PTKES GIZI | B8: Diisi oleh UPPS yang mengelola PS yang diakreditasi oleh LAM PTKES GIZI
A9: Form Monev UPPS LAMDIK | B9: Diisi oleh UPPS yang mengelola PS yang diakreditasi oleh LAMDIK
A10: Form Monev UPPS LAMEMBA | B10: Diisi oleh UPPS yang mengelola PS yang diakreditasi oleh LAMEMBA
A11: Form Monev UPPS LAMSAMA | B11: Diisi oleh UPPS yang mengelola PS yang diakreditasi oleh LAMSAMA
A12: Form Monev UPSS LAMTEK | B12: Diisi oleh UPPS yang mengelola PS yang diakreditasi oleh LAMTEK
... A26: Analisis SWOT | B26: Dapat Digunakan PS dan UPPS untuk menyusun Analisis SWOT

Sheet Isian Prodi
A1: ISIAN PROGRAM STUDI
A3: PETUNJUK PENGISIAN: SEL YANG DIISI PRODI HANYA YANG BERWARNA KUNING
A5: Nama Prodi : | C5: PRODI S2
A6: Nama UPPS : | C6: Fakultas/Departemen A
A7: Peringkat Terakreditasi : | C7: C
A8: Jenis prodi : (1 : Prodi sains teknologi; 2 : Prodi sosial humaniora)
A9: Jumlah kebutuhan lulusan : 1: Tinggi; 2: Rendah.
A11: Tabel 1 Jumlah Kerjasama Tridharma | G11: Konfirmasi Auditor
A12: Tahun Akademik | B12: Tingkat | C12: Pendidikan | D12: Penelitian | E12: Pengabdian kepada Masyarakat | G12: Tahun Akademik | H12: Tingkat | I12: Pendidikan | J12: Penelitian | K12: Pengabdian kepada Masyarakat
A13: 1 | B13: 2 | C13: 3 | D13: 4 | E13: 5 | G13: 1 | H13: 2 | I13: 3 | J13: 4 | K13: 5
A14: TS-2 | B14: Internasional | G14: TS-2 | H14: Internasional
A15: TS-1 | G15: TS-1
A16: TS | G16: TS
A17: Jumlah | C17: =SUM(C14:C16) -> 0 | D17: =SUM(D14:D16) -> 0 | E17: =SUM(E14:E16) -> 0 | G17: Jumlah | I17: =SUM(I14:I16) -> 0 | J17: =SUM(J14:J16) -> 0 | K17: =SUM(K14:K16) -> 0
A18: TS-2 | B18: Nasional | G18: TS-2 | H18: Nasional
A19: TS-1 | G19: TS-1
A20: TS | G20: TS
A21: Jumlah | C21: =SUM(C18:C20) -> 0 | D21: =SUM(D18:D20) -> 0 | E21: =SUM(E18:E20) -> 0 | G21: Jumlah | I21: =SUM(I18:I20) -> 0 | J21: =SUM(J18:J20) -> 0 | K21: =SUM(K18:K20) -> 0
A22: TS-2 | B22: Lokal/Wilayah | G22: TS-2 | H22: Lokal/Wilayah
A23: TS-1 | G23: TS-1
A24: TS | G24: TS
A25: Jumlah | C25: =SUM(C22:C24) -> 0 | D25: =SUM(D22:D24) -> 0 | E25: =SUM(E22:E24) -> 0 | G25: Jumlah | I25: =SUM(I22:I24) -> 0 | J25: =SUM(J22:J24) -> 0 | K25: =SUM(K22:K24) -> 0
A27: Tabel 2 Seleksi Mahasiswa Baru | J27: Konfirmasi Auditor
A28: Tahun Akademik | B28: Daya Tampung | C28: Jumlah Calon Mahasiswa | E28: Jumlah Mahasiswa Baru | G28: Jumlah Mahasiswa Aktif | J28: Tahun Akademik | K28: Daya Tampung | L28: Jumlah Calon Mahasiswa | N28: Jumlah Mahasiswa Baru | P28: Jumlah Mahasiswa Aktif
C29: Pendaftar | D29: Lulus Seleksi | E29: Reguler | F29: Transfer*) | G29: Reguler | H29: Transfer*) | L29: Pendaftar | M29: Lulus Seleksi | N29: Reguler | O29: Transfer*) | P29: Reguler | Q29: Transfer*)
A30: 1 | B30: 2 | C30: 3 | D30: 4 | E30: 5 | F30: 6 | G30: 7 | H30: 8 | J30: 1 | K30: 2 | L30: 3 | M30: 4 | N30: 5 | O30: 6 | P30: 7 | Q30: 8
A31: TS-4 | J31: TS-4
A32: TS-3 | J32: TS-3
A33: TS-2 | J33: TS-2
A34: TS-1 | J34: TS-1
A35: TS | J35: TS
A36: Jumlah | B36: =SUM(B31:B35) -> 0 | C36: =SUM(C31:C35) -> 0 | D36: =SUM(D31:D35) -> 0 | E36: =SUM(E31:E35) -> 0 | F36: =SUM(F31:F35) -> 0 | G36: =SUM(G35:H35) -> 0 | J36: Jumlah | K36: =SUM(K31:K35) -> 0 | L36: =SUM(L31:L35) -> 0 | M36: =SUM(M31:M35) -> 0 | N36: =SUM(N31:N35) -> 0 | O36: =SUM(O31:O35) -> 0 | P36: =SUM(P35:Q35) -> 0
A38: Tabel 3 Jumlah Mahasiswa Asing | E38: Konfirmasi Auditor
A39: Tahun Akademik | B39: Jumlah Mahasiswa Aktif | C39: Jumlah Mahasiswa Asing | E39: Tahun Akademik | F39: Jumlah Mahasiswa Aktif | G39: Jumlah Mahasiswa Asing
A40: 1 | B40: 2 | C40: 3 | E40: 1 | F40: 2 | G40: 3
A41: TS-4 | B41: =SUM(G31:H31) -> 0 | E41: TS-4 | F41: =SUM(K31:L31) -> 0
A42: TS-3 | B42: =SUM(G32:H32) -> 0 | E42: TS-3 | F42: =SUM(K32:L32) -> 0
A43: TS-2 | B43: =SUM(G33:H33) -> 0 | E43: TS-2 | F43: =SUM(K33:L33) -> 0
A44: TS-1 | B44: =SUM(G34:H34) -> 0 | E44: TS-1 | F44: =SUM(K34:L34) -> 0
A45: TS | B45: =SUM(G35:H35) -> 0 | E45: TS | F45: =SUM(K35:L35) -> 0
...

Sheet Kertas Kerja
A1: KERTAS KERJA AUDIT MUTU INTERNAL
A2: PROGRAM MAGISTER
A4: PETUNJUK PENGISIAN: SEL YANG DIISI PRODI HANYA YANG BERWARNA KUNING, SEL YANG DIISI auditor mutu INTERNAL HANYA YANG BERWARNA BIRU
A6: NO. | B6: ELEMEN | C6: INDIKATOR DAN PENILAIAN | E6: DOKUMEN BUKTI | F6: EVALUASI DIRI PROGRAM STUDI | G6: MANAJEMEN RISIKO | K6: SKOR AUDITOR MUTU | L6: DESKRIPSI TEMUAN AUDITOR MUTU INTERNAL | M6: REKOMENDASI AUDITOR MUTU INTERNAL | N6: VALIDATOR
G7: IDENTIFIKASI RISIKO | H7: TINGKAT KEMUNGKINAN | I7: SKALA DAMPAK | J7: LEVEL RISIKO
A8: 1 | B8: A | C8: Kondisi Eksternal Konsistensi dengan hasil analisis SWOT dan/atau analisis lain serta rencana pengembangan ke depan. | E8: (1) Laporan hasil analisis SWOT yang dilakukan maksimal dalam 2 tahun terakhir. (2) Rencana strategis fakultas yang telah disahkan dengan SK Rektor. | F8: Deskripsi dan penjelasan tentang : 1. Capaian terhadap indikator 2. Faktor pendukung dan faktor penghambat 3. Masalah dan akar masalah yang dihadapi 4. Data dan dokumen pendukung | G8: Deskripsi dan penjelasan tentang : 1. Peristiwa yang mungkin terjadi terkait dengan indikator 2. Dampak dari terjadinya peristiwa yang mungkin terjadi terkait dengan indikator | H8: A | I8: 1 | J8: =IF((IF(OR((H8&"."&I8)=$R$8,(H8&"."&I8)=$S$8,(H8&"."&I8)=$T$8,(H8&"."&I8)=$U$8,(H8&"."&I8)=$V$8,(H8&"."&I8)=$W$8),1,0))=1,"EKSTREM",IF((IF(OR((H8&"."&I8)=$R$9,(H8&"."&I8)=$S$9,(H8&"."&I8)=$T$9,(H8&"."&I8)=$U$9,(H8&"."&I8)=$V$9,(H8&"."&I8)=$W$9,(H8&"."&I8)=$X$9),1,0))=1,"TINGGI",IF((IF(OR((H8&"."&I8)=$R$10,(H8&"."&I8)=$S$10,(H8&"."&I8)=$T$10,(H8&"."&I8)=$U$10,(H8&"."&I8)=$V$10,(H8&"."&I8)=$W$10),1,0))=1,"MODERAT",IF((IF(OR((H8&"."&I8)=$R$11,(H8&"."&I8)=$S$11,(H8&"."&I8)=$T$11,(H8&"."&I8)=$U$11,(H8&"."&I8)=$V$11,(H8&"."&I8)=$W$11),1,0))=1,"RENDAH","-")))) -> RENDAH | K8: 0 | L8: Temuan Minor: (1) (2) (3) dst… Temuan Mayor: (1) (2) (3) dst… | M8: Rekomendasi berdasarkan temuan AMI, antara lain sebagai berikut: (1) (2) (3) dst… | P8: E | Q8: EKSTREM | R8: E.4 | S8: E.5 | T8: D.4 | U8: D.5 | V8: C.5 | W8: B.5
C9: 4 | D9: Unit Pengelola Program Studi (UPPS) mampu: 1) mengidentifikasi kondisi lingkungan dan industri yang relevan secara komprehensif dan strategis, 2) menetapkan posisi relatif program studi terhadap lingkungannya, 3) menggunakan hasil identifikasi dan posisi yang ditetapkan untuk melakukan analisis (SWOT/metoda analisis lain yang relevan) untuk pengembangan program studi, dan 4) merumuskan strategi pengembangan program studi yang berkesesuaian untuk menghasilkan program-program pengembangan alternatif yang tepat. | P9: T | Q9: TINGGI | R9: E.3 | S9: D.3 | T9: C.4 | U9: C.3 | V9: B.4 | W9: A.5 | X9: A.4
C10: 3 | D10: Unit Pengelola Program Studi (UPPS) mampu: 1) mengidentifikasi kondisi lingkungan dan industri yang relevan secara komprehensif, 2) menetapkan posisi relatif program studi terhadap lingkungannya, dan 3) menggunakan hasil identifikasi dan posisi yang ditetapkan untuk melakukan analisis (SWOT/metoda analisis lain yang relevan) untuk pengembangan program studi. | P10: M | Q10: MODERAT | R10: E.1 | S10: E.2 | T10: D.2 | U10: C.2 | V10: B.3 | W10: A.3
C11: 2 | D11: Unit Pengelola Program Studi (UPPS) mampu: 1) mengidentifikasi kondisi lingkungan dan industri yang relevan, dan 2) menetapkan posisi relatif program studi terhadap lingkungannya. | P11: R | Q11: RENDAH | R11: D.1 | S11: C.1 | T11: B.1 | U11: B.2 | V11: A.2 | W11: A.1
C12: 1 | D12: Unit Pengelola Program Studi (UPPS) kurang mampu: 1) mengidentifikasi kondisi lingkungan dan industri yang relevan, dan 2) menetapkan posisi relatif program studi terhadap lingkungannya.
C13: 0 | D13: Unit Pengelola Program Studi (UPPS) tidak mampu: 1) mengidentifikasi kondisi lingkungan dan industri yang relevan, dan 2) menetapkan posisi relatif program studi terhadap lingkungannya.
C14: Skor | K14: =IF(OR(ISBLANK(K8),K8<0,K8>4),0,K8) -> 0
A16: =A8+1 -> 2 | B16: B | C16: Profil Unit Pengelola Program Studi Keserbacakupan informasi dalam profil dan konsistensi antara profil dengan data dan informasi yang disampaikan pada masing-masing kriteria, serta menunjukkan iklim yang kondusif untuk pengembangan dan reputasi sebagai rujukan di bidang keilmuannya. | E16: (1) Profil fakultas yang memuat visi misi, gambaran umum tata pamong, sistem admisi, layanan kemahasiswaan yang tersedia, kualitas dan kuantitas dosen serta tenaga kependidikan, biaya pendidikan, sarana prasarana yang tersedia, kurikulum, karya penelitian dan PkM dosen, produk unggulan fakultas dan program studi, serta informasi lain yang relevan. | F16: Deskripsi dan penjelasan tentang : 1. Capaian terhadap indikator 2. Faktor pendukung dan faktor penghambat 3. Masalah dan akar masalah yang dihadapi 4. Data dan dokumen pendukung | G16: Deskripsi dan penjelasan tentang : 1. Peristiwa yang mungkin terjadi terkait dengan indikator 2. Dampak dari terjadinya peristiwa yang mungkin terjadi terkait dengan indikator | H16: A | I16: 1 | J16: =IF((IF(OR((H16&"."&I16)=$R$8,(H16&"."&I16)=$S$8,(H16&"."&I16)=$T$8,(H16&"."&I16)=$U$8,(H16&"."&I16)=$V$8,(H16&"."&I16)=$W$8),1,0))=1,"EKSTREM",IF((IF(OR((H16&"."&I16)=$R$9,(H16&"."&I16)=$S$9,(H16&"."&I16)=$T$9,(H16&"."&I16)=$U$9,(H16&"."&I16)=$V$9,(H16&"."&I16)=$W$9,(H16&"."&I16)=$X$9),1,0))=1,"TINGGI",IF((IF(OR((H16&"."&I16)=$R$10,(H16&"."&I16)=$S$10,(H16&"."&I16)=$T$10,(H16&"."&I16)=$U$10,(H16&"."&I16)=$V$10,(H16&"."&I16)=$W$10),1,0))=1,"MODERAT",IF((IF(OR((H16&"."&I16)=$R$11,(H16&"."&I16)=$S$11,(H16&"."&I16)=$T$11,(H16&"."&I16)=$U$11,(H16&"."&I16)=$V$11,(H16&"."&I16)=$W$11),1,0))=1,"RENDAH","-")))) -> RENDAH | K16: 0 | L16: Temuan Minor: (1) (2) (3) dst… Temuan Mayor: (1) (2) (3) dst… | M16: Rekomendasi berdasarkan temuan AMI, antara lain sebagai berikut: (1) (2) (3) dst…
C17: 4 | D17: Profil UPPS: 1) menunjukkan keserbacakupan informasi yang jelas dan konsisten dengan data dan informasi yang disampaikan pada masing-masing kriteria, 2) menggambarkan keselarasan dengan substansi keilmuan program studi. 3) menunjukkan iklim yang kondusif untuk pengembangan keilmuan program studi. 4) menunjukkan reputasi sebagai rujukan di bidang keilmuannya.
C18: 3 | D18: Profil UPPS: 1) menunjukkan keserbacakupan informasi yang jelas dan konsisten dengan data dan informasi yang disampaikan pada masing-masing kriteria, 2) menggambarkan keselarasan dengan substansi keilmuan program studi. 3) menunjukkan iklim yang kondusif untuk pengembangan keilmuan program studi.
C19: 2 | D19: Profil UPPS: 1) menunjukkan keserbacakupan informasi yang jelas dengan data dan informasi yang disampaikan pada masing-masing kriteria, 2) menggambarkan keselarasan dengan substansi keilmuan program studi.
C20: 1 | D20: Profil UPPS: 1) kurang menunjukkan keserbacakupan informasi yang jelas dengan data dan informasi yang disampaikan pada masing-masing kriteria, 2) kurang menggambarkan keselarasan dengan substansi keilmuan program studi.
C21: 0 | D21: Profil UPPS tidak menunjukkan keserbacakupan informasi yang jelas dengan data dan informasi yang disampaikan pada masing-masing kriteria.
C22: Skor | K22: =IF(OR(ISBLANK(K16),K16<0,K16>4),0,K16) -> 0
A24: =A16+1 -> 3 | B24: C Kriteria C.1 Visi, Misi, Tujuan dan Strategi C.1.4 Indikator Kinerja Utama | C24: Kesesuaian Visi, Misi, Tujuan dan Strategi (VMTS) Unit Pengelola Program Studi (UPPS) terhadap VMTS Perguruan Tinggi (PT) dan visi keilmuan Program Studi (PS) yang dikelolanya. | E24: (1) VMTS fakultas yang telah disahkan dengan SK Rektor (2) Visi keilmuan program studi yang telah disahkan dengan SK Rektor | F24: Deskripsi dan penjelasan tentang : 1. Capaian terhadap indikator 2. Faktor pendukung dan faktor penghambat 3. Masalah dan akar masalah yang dihadapi 4. Data dan dokumen pendukung | G24: Deskripsi dan penjelasan tentang : 1. Peristiwa yang mungkin terjadi terkait dengan indikator 2. Dampak dari terjadinya peristiwa yang mungkin terjadi terkait dengan indikator | H24: A | I24: 1 | J24: =IF((IF(OR((H24&"."&I24)=$R$8,(H24&"."&I24)=$S$8,(H24&"."&I24)=$T$8,(H24&"."&I24)=$U$8,(H24&"."&I24)=$V$8,(H24&"."&I24)=$W$8),1,0))=1,"EKSTREM",IF((IF(OR((H24&"."&I24)=$R$9,(H24&"."&I24)=$S$9,(H24&"."&I24)=$T$9,(H24&"."&I24)=$U$9,(H24&"."&I24)=$V$9,(H24&"."&I24)=$W$9,(H24&"."&I24)=$X$9),1,0))=1,"TINGGI",IF((IF(OR((H24&"."&I24)=$R$10,(H24&"."&I24)=$S$10,(H24&"."&I24)=$T$10,(H24&"."&I24)=$U$10,(H24&"."&I24)=$V$10,(H24&"."&I24)=$W$10),1,0))=1,"MODERAT",IF((IF(OR((H24&"."&I24)=$R$11,(H24&"."&I24)=$S$11,(H24&"."&I24)=$T$11,(H24&"."&I24)=$U$11,(H24&"."&I24)=$V$11,(H24&"."&I24)=$W$11),1,0))=1,"RENDAH","-")))) -> RENDAH | K24: 0 | L24: Temuan Minor: (1) (2) (3) dst… Temuan Mayor: (1) (2) (3) dst… | M24: Rekomendasi berdasarkan temuan AMI, antara lain sebagai berikut: (1) (2) (3) dst…
C25: 4 | D25: UPPS memiliki: 1) visi yang mencerminkan visi perguruan tinggi dan memayungi visi keilmuan terkait keunikan program studi serta didukung data konsistensi implementasinya, 2) misi, tujuan, dan strategi yang searah dan bersinerji dengan misi, tujuan, dan strategi perguruan tinggi serta mendukung pengembangan program studi dengan data konsistensi implementasinya.
C26: 3 | D26: UPPS memiliki: 1) visi yang mencerminkan visi perguruan tinggi dan memayungi visi keilmuan terkait keunikan program studi, 2) misi, tujuan, dan strategi yang searah dan bersinerji dengan misi, tujuan, dan strategi perguruan tinggi serta mendukung pengembangan program studi.
C27: 2 | D27: UPPS memiliki: 1) visi yang mencerminkan visi perguruan tinggi dan memayungi visi keilmuan terkait program studi, 2) misi, tujuan, dan strategi yang searah dengan misi, tujuan, dan strategi perguruan tinggi serta mendukung pengembangan program studi.
C28: 1 | D28: UPPS memiliki: 1) visi yang mencerminkan visi perguruan tinggi namun tidak memayungi visi keilmuan terkait program studi, 2) misi, tujuan, dan strategi kurang searah dengan misi, tujuan sasaran, dan strategi perguruan tinggi serta kurang mendukung pengembangan program studi.
C29: 0 | D29: UPPS memiliki misi, tujuan, dan strategi yang tidak terkait dengan strategi perguruan tinggi dan pengembangan program studi.
C30: Skor | K30: =IF(OR(ISBLANK(K24),K24<0,K24>4),0,K24) -> 0
A32: =A24+1 -> 4 | C32: Mekanisme dan keterlibatan pemangku kepentingan dalam penyusunan VMTS UPPS. | E32: (1) Prosedur/Panduan Penyusunan Pemutakhiran VMTS Fakultas dan Prodi (2) Laporan penyusunan VMTS yang memuat pelibatan pemangku kepentingan internal dan eksternal, berita acara/ dokumentasi/ notulen keterlibatan pihak internal dan eksternal. | F32: Deskripsi dan penjelasan tentang : 1. Capaian terhadap indikator 2. Faktor pendukung dan faktor penghambat 3. Masalah dan akar masalah yang dihadapi 4. Data dan dokumen pendukung | G32: Deskripsi dan penjelasan tentang : 1. Peristiwa yang mungkin terjadi terkait dengan indikator 2. Dampak dari terjadinya peristiwa yang mungkin terjadi terkait dengan indikator | H32: A | I32: 1 | J32: =IF((IF(OR((H32&"."&I32)=$R$8,(H32&"."&I32)=$S$8,(H32&"."&I32)=$T$8,(H32&"."&I32)=$U$8,(H32&"."&I32)=$V$8,(H32&"."&I32)=$W$8),1,0))=1,"EKSTREM",IF((IF(OR((H32&"."&I32)=$R$9,(H32&"."&I32)=$S$9,(H32&"."&I32)=$T$9,(H32&"."&I32)=$U$9,(H32&"."&I32)=$V$9,(H32&"."&I32)=$W$9,(H32&"."&I32)=$X$9),1,0))=1,"TINGGI",IF((IF(OR((H32&"."&I32)=$R$10,(H32&"."&I32)=$S$10,(H32&"."&I32)=$T$10,(H32&"."&I32)=$U$10,(H32&"."&I32)=$V$10,(H32&"."&I32)=$W$10),1,0))=1,"MODERAT",IF((IF(OR((H32&"."&I32)=$R$11,(H32&"."&I32)=$S$11,(H32&"."&I32)=$T$11,(H32&"."&I32)=$U$11,(H32&"."&I32)=$V$11,(H32&"."&I32)=$W$11),1,0))=1,"RENDAH","-")))) -> RENDAH | K32: 0 | L32: Temuan Minor: (1) (2) (3) dst… Temuan Mayor: (1) (2) (3) dst… | M32: Rekomendasi berdasarkan temuan AMI, antara lain sebagai berikut: (1) (2) (3) dst…
C33: 4 | D33: Ada mekanisme dalam penyusunan dan penetapan visi, misi, tujuan dan strategi yang terdokumentasi serta ada keterlibatan semua pemangku kepentingan internal (dosen, mahasiswa dan tenaga kependidikan) dan eksternal (lulusan, pengguna lulusan dan pakar/mitra/organisasi profesi/pemerintah).
C34: 3 | D34: Ada mekanisme dalam penyusunan dan penetapan visi, misi, tujuan dan strategi yang terdokumentasi serta ada keterlibatan pemangku kepentingan internal (dosen, mahasiswa dan tenaga kependidikan) dan pemangku kepentingan eksternal (lulusan dan pengguna lulusan).
C35: 2 | D35: Ada mekanisme dalam penyusunan dan penetapan visi, misi, tujuan dan strategi yang terdokumentasi serta ada keterlibatan pemangku kepentingan internal (dosen dan mahasiswa) dan pemangku kepentingan eksternal (lulusan).
C36: 1 | D36: Ada mekanisme dalam penyusunan dan penetapan visi, misi, tujuan dan strategi yang terdokumentasi namun tidak melibatkan pemangku kepentingan.
C37: 0 | D37: Tidak ada mekanisme dalam penyusunan dan penetapan visi, misi, tujuan dan strategi.
C38: Skor | K38: =IF(OR(ISBLANK(K32),K32<0,K32>4),0,K32) -> 0
A40: =A32+1 -> 5 | C40: Strategi pencapaian tujuan disusun berdasarkan analisis yang sistematis, serta pada pelaksanaannya dilakukan pemantauan dan evaluasi yang ditindaklanjuti. | E40: (1) Rencana strategis fakultas yang telah disahkan dengan SK Rektor. | F40: Deskripsi dan penjelasan tentang : 1. Capaian terhadap indikator 2. Faktor pendukung dan faktor penghambat 3. Masalah dan akar masalah yang dihadapi 4. Data dan dokumen pendukung | G40: Deskripsi dan penjelasan tentang : 1. Peristiwa yang mungkin terjadi terkait dengan indikator 2. Dampak dari terjadinya peristiwa yang mungkin terjadi terkait dengan indikator | H40: A | I40: 1 | J40: =IF((IF(OR((H40&"."&I40)=$R$8,(H40&"."&I40)=$S$8,(H40&"."&I40)=$T$8,(H40&"."&I40)=$U$8,(H40&"."&I40)=$V$8,(H40&"."&I40)=$W$8),1,0))=1,"EKSTREM",IF((IF(OR((H40&"."&I40)=$R$9,(H40&"."&I40)=$S$9,(H40&"."&I40)=$T$9,(H40&"."&I40)=$U$9,(H40&"."&I40)=$V$9,(H40&"."&I40)=$W$9,(H40&"."&I40)=$X$9),1,0))=1,"TINGGI",IF((IF(OR((H40&"."&I40)=$R$10,(H40&"."&I40)=$S$10,(H40&"."&I40)=$T$10,(H40&"."&I40)=$U$10,(H40&"."&I40)=$V$10,(H40&"."&I40)=$W$10),1,0))=1,"MODERAT",IF((IF(OR((H40&"."&I40)=$R$11,(H40&"."&I40)=$S$11,(H40&"."&I40)=$T$11,(H40&"."&I40)=$U$11,(H40&"."&I40)=$V$11,(H40&"."&I40)=$W$11),1,0))=1,"RENDAH","-")))) -> RENDAH | K40: 0 | L40: Temuan Minor: (1) (2) (3) dst… Temuan Mayor: (1) (2) (3) dst… | M40: Rekomendasi berdasarkan temuan AMI, antara lain sebagai berikut: (1) (2) (3) dst…
C41: 4 | D41: Strategi efektif untuk mencapai tujuan dan disusun berdasarkan analisis yang sistematis dengan menggunakan metoda yang relevan dan terdokumentasi serta pada pelaksanaannya dilakukan pemantauan dan evaluasi dan ditindaklanjuti.
C42: 3 | D42: Strategi efektif untuk mencapai tujuan dan disusun berdasarkan analisis yang sistematis dengan menggunakan metoda yang relevan dan terdokumentasi serta pada pelaksanaannya dilakukan pemantauan dan evaluasi.
C43: 2 | D43: Strategi untuk mencapai tujuan dan disusun berdasarkan analisis yang sistematis dengan menggunakan metoda yang relevan serta terdokumentasi namun belum terbukti efektifitasnya.
C44: 1 | D44: Strategi untuk mencapai tujuan disusun berdasarkan analisis yang kurang sistematis serta tidak menggunakan metoda yang relevan.
C45: 0 | D45: Tidak memiliki strategi untuk mencapai tujuan.
C46: Skor | K46: =IF(OR(ISBLANK(K40),K40<0,K40>4),0,K40) -> 0
...

Sheet Form Monev PT
B1: FORMULIR MONITORING DAN EVALUASI KINERJA LEVEL INSTITUSI
A3: No. | B3: Nama Standar | C3: Indikator | D3: Kode Indikator | E3: Sumber | F3: Persentase Capaian (tuliskan seberapa besar persentase pencapaian institusi terhadap setiap indikator, persentase dituliskan berdasarkan penilaian pimpinan PT/evaluasi diri) | G3: Evaluasi Diri (deskripsikan data capaian indikator, dapat berupa data kuantitatif/kualitatif, faktor pendukung/penghambat, masalah yang dihadapi, dan link dokumen bukti) | H3: Tindak Lanjut (tuliskan tindak lanjut yang dilakukan untuk memperbaiki atau meningkatkan capaian indikator)
A4: 1 | B4: Standar Kompetensi Lulusan | C4: Tercapainya persentase lulusan yang melanjutkan studi minimal sebesar 10% dari total lulusan. | D4: S.001/022 | E4: QS STARS RATING
A5: 2 | B5: Standar Kompetensi Lulusan | C5: Tercapainya jumlah penghargaan yang diterima dari aspek seni dan budaya sebanyak 1 penghargaan per fakultas per tahun. | D5: S.001/023 | E5: QS STARS RATING
A6: 3 | B6: Standar Isi Pembelajaran | C6: Tersedianya kebijakan pengembangan kurikulum UKSW yang mempertimbangkan keterkaitan dengan visi dan misi UKSW, pengembangan ilmu pengetahuan dan kebutuhan stakeholder yang komprehensif dan mempertimbangkan perubahan di masa depan. | D6: S.002/001 | E6: APT, LAMDIK
A7: 4 | B7: Standar Isi Pembelajaran | C7: Tersedianya pedoman pengembangan kurikulum program studi di UKSW yang memuat profil lulusan, capaian pembelajaran yang mengacu kepada KKNI, bahan kajian, struktur kurikulum dan rencana pembelajaran semester (RPS) yang mengacu ke SN-DIKTI dan benchmark pada institusi internasional, peraturan terkini, dan kepekaan terhadap isu-isu terkini. | D7: S.002/002 | E7: APT
A8: 5 | B8: Standar Isi Pembelajaran | C8: Tersedianya mekanisme penetapan (legalitas) kurikulum yang melibatkan unsur-unsur yang berwenang dalam institusi secara akuntabel dan transparan. | D8: S.002/003 | E8: APT
A9: 6 | B9: Standar Isi Pembelajaran | C9: Tersedianya pedoman implementasi kurikulum yang mencakup perencanaan, pelaksanaan, pemantauan, dan peninjauan kurikulum. | D9: S.002/004 | E9: APT
A10: 7 | B10: Standar Proses Pembelajaran | C10: Tersedia pedoman penerapan sistem penugasan dosen berdasarkan kebutuhan, kualifikasi, keahlian dan pengalaman. | D10: S.003/001 | E10: APT
A11: 8 | B11: Standar Proses Pembelajaran | C11: Tersedia bukti yang sahih tentang penetapan strategi, metode, media pembelajaran dan penilaian pembelajaran | D11: S.003/002 | E11: APT
A12: 9 | B12: Standar Proses Pembelajaran | C12: Tersedia dan terimplementasi sistem monev pelaksanaan dan mutu proses pembelajaran. | D12: S.003/003 | E12: APT
A13: 10 | B13: Standar Proses Pembelajaran | C13: Tersedia kebijakan dan pedoman untuk mengintegrasikan kegiatan penelitian dan PkM ke dalam pembelajaran. | D13: S.003/004 | E13: APT
A14: 11 | B14: Standar Proses Pembelajaran | C14: Tersedia bukti yang sahih tentang pelaksanaan, evaluasi, pengendalian, dan peningkatan kualitas secara berkelanjutan integrasi kegiatan penelitian dan PkM ke dalam pembelajaran, serta bukti yang sahih bahwa terlaksana monitoring dan evaluasi integrasi penelitian dan PkM ke dalam pembelajaran. | D14: S.003/005 | E14: APT
A15: 12 | B15: Standar Proses Pembelajaran | C15: Tersedia dan terlaksana Kode Etik Mahasiswa dalam pembelajaran. | D15: S.003/016 | E15: UKSW
... A115: 112 | B115: Standar Kerjasama Kelembagaan | C115: Tersedia bukti monitoring dan evaluasi pelaksanaan program kemitraan, tingkat kepuasan mitra kerjasama yang diukur dengan instrumen yang sahih, serta upaya perbaikan mutu jejaring dan kemitraan untuk menjamin ketercapaian visi, misi dan tujuan strategis UKSW. | D115: S.029/003 | E115: APT

Sheet Form Monev UPPS BAN-PT
A1: FORMULIR MONITORING DAN EVALUASI KINERJA LEVEL UNIT PENGELOLA PROGRAM STUDI (BAN-PT)
A3: No. | B3: Nama Standar | C3: Indikator | D3: Kode Indikator | E3: Sumber | F3: Persentase Capaian (tuliskan seberapa besar persentase pencapaian UPPS terhadap setiap indikator, persentase dituliskan berdasarkan penilaian pimpinan PT/evaluasi diri) | G3: Evaluasi Diri (deskripsikan data capaian indikator, dapat berupa data kuantitatif/kualitatif, faktor pendukung/penghambat, masalah yang dihadapi, dan link dokumen bukti) | H3: Tindak Lanjut (tuliskan tindak lanjut yang dilakukan untuk memperbaiki atau meningkatkan capaian indikator)
A4: 1 | B4: Standar Sarana dan Prasarana Pembelajaran | C4: Terlaksana pengembangan sarana pembelajaran di semua fakultas setiap tahun. | D4: S.006/006 | E4: UKSW
A5: 2 | B5: Standar Sarana dan Prasarana Pembelajaran | C5: Tersedia laboratorium microteaching, lengkap dengan perlengkapan dan peralatan yang mutakhir dan terawat. | D5: S.006/007 | E5: QS STARS RATING
A6: 3 | B6: Standar Pengelolaan Pembelajaran | C6: Tersedia Rencana Strategis dan Rencana Operasional yang memuat rencana pelaksanaan program pembelajaran | D6: S.007/001 | E6: SN DIKTI
A7: 4 | B7: Standar Pengelolaan Pembelajaran | C7: Terlaksana program pembelajaran sesuai dengan Rencana Strategis dan Rencana Operasional. | D7: S.007/002 | E7: SN DIKTI
A8: 5 | B8: Standar Pengelolaan Pembelajaran | C8: Terlaksana penjaminan mutu pengelolaan Program Studi dalam melaksanakan program Pembelajaran secara berkelanjutan dengan sasaran yang sesuai dengan visi dan misi. | D8: S.007/003 | E8: SN DIKTI
A9: 6 | B9: Standar Pengelolaan Pembelajaran | C9: Terlaksana pemantauan dan evaluasi terhadap kegiatan Program Studi dalam melaksanakan kegiatan Pembelajaran. | D9: S.007/004 | E9: SN DIKTI
A10: 7 | B10: Standar Pengelolaan Pembelajaran | C10: Tersedia panduan perencanaan, pelaksanaan, evaluasi, pengawasan, penjaminan mutu, dan pengembangan kegiatan Pembelajaran dan Dosen | D10: S.007/005 | E10: SN DIKTI
A11: 8 | B11: Standar Pengelolaan Pembelajaran | C11: Terlaksana pelaporan kinerja Program Studi dalam menyelenggarakan program Pembelajaran melalui pangkalan data Pendidikan Tinggi. | D11: S.007/006 | E11: SN DIKTI
A12: 9 | B12: Standar Pengelolaan Pembelajaran | C12: Terdokumentasi seluruh proses pembelajaran, mulai dari perencanaan, pelaksanaan, pengendalian, pemantauan dan evaluasi, serta pelaporan kegiatan pembelajaran pada SIIMUT. | D12: S.007/007 | E12: UKSW
A13: 10 | B13: Standar Pengelolaan Pembelajaran | C13: Tersedia dan terselenggara sistem aduan akademik untuk mahasiswa untuk menyelesaikan masalah-masalah akademik dengan tingkat persentase penyelesaian masalah mencapai 100% | D13: S.007/008 | E13: UKSW
A14: 11 | B14: Standar Pembiayaan Pembelajaran | C14: Tercapainya jumlah pendapatan institusi pada bidang pendidikan minimal sebesar Rp20 juta per mahasiswa per tahun | D14: S.008/013 | E14: THE
A15: 12 | B15: Standar Penilaian Penelitian | C15: Tersedia reviewer penelitian tingkat nasional yang tersertifikasi minimal 1 orang per fakultas. | D15: S.012/004 | E15: UKSW
... A50: 47 | B50: Standar Kerjasama Kelembagaan | C50: Tersedia mitra kerjasama baru minimal 5 mitra setiap tahun. | D50: S.029/007 | E50: UKSW

Sheet Form Monev UPPS LAM INFOKOM
A1: FORMULIR MONITORING DAN EVALUASI KINERJA LEVEL UNIT PENGELOLA PROGRAM STUDI (LAM INFOKOM)
A3: No. | B3: Nama Standar | C3: Indikator | D3: Kode Indikator | E3: Sumber | F3: Persentase Capaian (tuliskan seberapa besar persentase pencapaian UPPS terhadap setiap indikator, persentase dituliskan berdasarkan penilaian pimpinan PT/evaluasi diri) | G3: Evaluasi Diri (deskripsikan data capaian indikator, dapat berupa data kuantitatif/kualitatif, faktor pendukung/penghambat, masalah yang dihadapi, dan link dokumen bukti) | H3: Tindak Lanjut (tuliskan tindak lanjut yang dilakukan untuk memperbaiki atau meningkatkan capaian indikator)
A4: 1 | B4: Standar Dosen dan Tendik | C4: Tersedia dan terimplementasi kebijakan, pedoman dan instrumen survei kepuasan dosen dan tenaga kependidikan terhadap pengelolaan SDM yang dilaksanakan secara rutin setiap tahun, berkesinambungan, hasilnya dilaporkan dan ditindaklanjuti. | D4: S.005/022 | E4: LAM INFOKOM
A5: 2 | B5: Standar Dosen dan Tendik | C5: Tersedia dan terimplementasi kebijakan, pedoman dan instrumen survei kepuasan dosen dan tenaga kependidikan terhadap pengelolaan SDM yang dilaksanakan secara rutin setiap tahun, berkesinambungan, hasilnya dilaporkan dan ditindaklanjuti. | D5: S.005/023 | E5: LAM INFOKOM
A6: 3 | B6: Standar Dosen dan Tendik | C6: Tersedia dan terimplementasi kebijakan dan pedoman pengembangan karir dosen dan tenaga kependidikan yang terlaksana secara konsisten dan terdokumentasi dengan baik. | D6: S.005/024 | E6: LAM INFOKOM
A7: 4 | B7: Standar Dosen dan Tendik | C7: Tersedia dan terimplementasi kebijakan dan pedoman pengembangan karir dosen dan tenaga kependidikan yang terlaksana secara konsisten dan terdokumentasi dengan baik. | D7: S.005/025 | E7: LAM INFOKOM
A8: 5 | B8: Standar Sarana dan Prasarana Pembelajaran | C8: Terlaksana pengembangan sarana pembelajaran di semua fakultas setiap tahun. | D8: S.006/006 | E8: UKSW
A9: 6 | B9: Standar Sarana dan Prasarana Pembelajaran | C9: Tersedia laboratorium microteaching, lengkap dengan perlengkapan dan peralatan yang mutakhir dan terawat. | D9: S.006/007 | E9: QS STARS RATING
A10: 7 | B10: Standar Pengelolaan Pembelajaran | C10: Tersedia Rencana Strategis dan Rencana Operasional yang memuat rencana pelaksanaan program pembelajaran | D10: S.007/001 | E10: SN DIKTI
A11: 8 | B11: Standar Pengelolaan Pembelajaran | C11: Terlaksana program pembelajaran sesuai dengan Rencana Strategis dan Rencana Operasional. | D11: S.007/002 | E11: SN DIKTI
A12: 9 | B12: Standar Pengelolaan Pembelajaran | C12: Terlaksana penjaminan mutu pengelolaan Program Studi dalam melaksanakan program Pembelajaran secara berkelanjutan dengan sasaran yang sesuai dengan visi dan misi. | D12: S.007/003 | E12: SN DIKTI
A13: 10 | B13: Standar Pengelolaan Pembelajaran | C13: Terlaksana pemantauan dan evaluasi terhadap kegiatan Program Studi dalam melaksanakan kegiatan Pembelajaran. | D13: S.007/004 | E13: SN DIKTI
A14: 11 | B14: Standar Pengelolaan Pembelajaran | C14: Tersedia panduan perencanaan, pelaksanaan, evaluasi, pengawasan, penjaminan mutu, dan pengembangan kegiatan Pembelajaran dan Dosen | D14: S.007/005 | E14: SN DIKTI
A15: 12 | B15: Standar Pengelolaan Pembelajaran | C15: Terlaksana pelaporan kinerja Program Studi dalam menyelenggarakan program Pembelajaran melalui pangkalan data Pendidikan Tinggi. | D15: S.007/006 | E15: SN DIKTI
... A62: 59 | B62: Standar Kerjasama Kelembagaan | C62: Tersedia mitra kerjasama baru minimal 5 mitra setiap tahun. | D62: S.029/007 | E62: UKSW

Sheet Form Monev UPPS LAM PTKES NERS
A1: FORMULIR MONITORING DAN EVALUASI KINERJA LEVEL UNIT PENGELOLA PROGRAM STUDI (LAM PT-KES NERS)
A3: No. | B3: Nama Standar | C3: Indikator | D3: Kode Indikator | E3: Sumber | F3: Persentase Capaian (tuliskan seberapa besar persentase pencapaian UPPS terhadap setiap indikator, persentase dituliskan berdasarkan penilaian pimpinan PT/evaluasi diri) | G3: Evaluasi Diri (deskripsikan data capaian indikator, dapat berupa data kuantitatif/kualitatif, faktor pendukung/penghambat, masalah yang dihadapi, dan link dokumen bukti) | H3: Tindak Lanjut (tuliskan tindak lanjut yang dilakukan untuk memperbaiki atau meningkatkan capaian indikator)
A4: 1 | B4: Standar Sarana dan Prasarana Pembelajaran | C4: Terlaksana pengembangan sarana pembelajaran di semua fakultas setiap tahun. | D4: S.006/006 | E4: UKSW
A5: 2 | B5: Standar Sarana dan Prasarana Pembelajaran | C5: Tersedia laboratorium microteaching, lengkap dengan perlengkapan dan peralatan yang mutakhir dan terawat. | D5: S.006/007 | E5: QS STARS RATING
A6: 3 | B6: Standar Pengelolaan Pembelajaran | C6: Tersedia Rencana Strategis dan Rencana Operasional yang memuat rencana pelaksanaan program pembelajaran | D6: S.007/001 | E6: SN DIKTI
A7: 4 | B7: Standar Pengelolaan Pembelajaran | C7: Terlaksana program pembelajaran sesuai dengan Rencana Strategis dan Rencana Operasional. | D7: S.007/002 | E7: SN DIKTI
A8: 5 | B8: Standar Pengelolaan Pembelajaran | C8: Terlaksana penjaminan mutu pengelolaan Program Studi dalam melaksanakan program Pembelajaran secara berkelanjutan dengan sasaran yang sesuai dengan visi dan misi. | D8: S.007/003 | E8: SN DIKTI
A9: 6 | B9: Standar Pengelolaan Pembelajaran | C9: Terlaksana pemantauan dan evaluasi terhadap kegiatan Program Studi dalam melaksanakan kegiatan Pembelajaran. | D9: S.007/004 | E9: SN DIKTI
A10: 7 | B10: Standar Pengelolaan Pembelajaran | C10: Tersedia panduan perencanaan, pelaksanaan, evaluasi, pengawasan, penjaminan mutu, dan pengembangan kegiatan Pembelajaran dan Dosen | D10: S.007/005 | E10: SN DIKTI
A11: 8 | B11: Standar Pengelolaan Pembelajaran | C11: Terlaksana pelaporan kinerja Program Studi dalam menyelenggarakan program Pembelajaran melalui pangkalan data Pendidikan Tinggi. | D11: S.007/006 | E11: SN DIKTI
A12: 9 | B12: Standar Pengelolaan Pembelajaran | C12: Terdokumentasi seluruh proses pembelajaran, mulai dari perencanaan, pelaksanaan, pengendalian, pemantauan dan evaluasi, serta pelaporan kegiatan pembelajaran pada SIIMUT. | D12: S.007/007 | E12: UKSW
A13: 10 | B13: Standar Pengelolaan Pembelajaran | C13: Tersedia dan terselenggara sistem aduan akademik untuk mahasiswa untuk menyelesaikan masalah-masalah akademik dengan tingkat persentase penyelesaian masalah mencapai 100% | D13: S.007/008 | E13: UKSW
A14: 11 | B14: Standar Pembiayaan Pembelajaran | C14: Terlaksana audit internal terhadap pengelolaan keuangan di UPPS. | D14: S.008/012 | E14: LAM PT-KES NERS
A15: 12 | B15: Standar Pembiayaan Pembelajaran | C15: Tercapainya jumlah pendapatan institusi pada bidang pendidikan minimal sebesar Rp20 juta per mahasiswa per tahun | D15: S.008/013 | E15: THE
... A55: 52 | B55: Standar Kerjasama Kelembagaan | C55: Tersedia mitra kerjasama baru minimal 5 mitra setiap tahun. | D55: S.029/007 | E55: UKSW

Sheet Form Monev UPPS LAM PTKES GIZI
A1: FORMULIR MONITORING DAN EVALUASI KINERJA LEVEL UNIT PENGELOLA PROGRAM STUDI (LAM PT-KES GIZI)
A3: No. | B3: Nama Standar | C3: Indikator | D3: Kode Indikator | E3: Sumber | F3: Persentase Capaian (tuliskan seberapa besar persentase pencapaian UPPS terhadap setiap indikator, persentase dituliskan berdasarkan penilaian pimpinan PT/evaluasi diri) | G3: Evaluasi Diri (deskripsikan data capaian indikator, dapat berupa data kuantitatif/kualitatif, faktor pendukung/penghambat, masalah yang dihadapi, dan link dokumen bukti) | H3: Tindak Lanjut (tuliskan tindak lanjut yang dilakukan untuk memperbaiki atau meningkatkan capaian indikator)
A4: 1 | B4: Standar Sarana dan Prasarana Pembelajaran | C4: Terlaksana pengembangan sarana pembelajaran di semua fakultas setiap tahun. | D4: S.006/006 | E4: UKSW
A5: 2 | B5: Standar Sarana dan Prasarana Pembelajaran | C5: Tersedia laboratorium microteaching, lengkap dengan perlengkapan dan peralatan yang mutakhir dan terawat. | D5: S.006/007 | E5: QS STARS RATING
A6: 3 | B6: Standar Pengelolaan Pembelajaran | C6: Tersedia Rencana Strategis dan Rencana Operasional yang memuat rencana pelaksanaan program pembelajaran | D6: S.007/001 | E6: SN DIKTI
A7: 4 | B7: Standar Pengelolaan Pembelajaran | C7: Terlaksana program pembelajaran sesuai dengan Rencana Strategis dan Rencana Operasional. | D7: S.007/002 | E7: SN DIKTI
A8: 5 | B8: Standar Pengelolaan Pembelajaran | C8: Terlaksana penjaminan mutu pengelolaan Program Studi dalam melaksanakan program Pembelajaran secara berkelanjutan dengan sasaran yang sesuai dengan visi dan misi. | D8: S.007/003 | E8: SN DIKTI
A9: 6 | B9: Standar Pengelolaan Pembelajaran | C9: Terlaksana pemantauan dan evaluasi terhadap kegiatan Program Studi dalam melaksanakan kegiatan Pembelajaran. | D9: S.007/004 | E9: SN DIKTI
A10: 7 | B10: Standar Pengelolaan Pembelajaran | C10: Tersedia panduan perencanaan, pelaksanaan, evaluasi, pengawasan, penjaminan mutu, dan pengembangan kegiatan Pembelajaran dan Dosen | D10: S.007/005 | E10: SN DIKTI
A11: 8 | B11: Standar Pengelolaan Pembelajaran | C11: Terlaksana pelaporan kinerja Program Studi dalam menyelenggarakan program Pembelajaran melalui pangkalan data Pendidikan Tinggi. | D11: S.007/006 | E11: SN DIKTI
A12: 9 | B12: Standar Pengelolaan Pembelajaran | C12: Terdokumentasi seluruh proses pembelajaran, mulai dari perencanaan, pelaksanaan, pengendalian, pemantauan dan evaluasi, serta pelaporan kegiatan pembelajaran pada SIIMUT. | D12: S.007/007 | E12: UKSW
A13: 10 | B13: Standar Pengelolaan Pembelajaran | C13: Tersedia dan terselenggara sistem aduan akademik untuk mahasiswa untuk menyelesaikan masalah-masalah akademik dengan tingkat persentase penyelesaian masalah mencapai 100% | D13: S.007/008 | E13: UKSW
A14: 11 | B14: Standar Pembiayaan Pembelajaran | C14: Terlaksana audit internal terhadap pengelolaan keuangan di UPPS. | D14: S.008/012 | E14: LAM PT-KES GIZI
A15: 12 | B15: Standar Pembiayaan Pembelajaran | C15: Tercapainya jumlah pendapatan institusi pada bidang pendidikan minimal sebesar Rp20 juta per mahasiswa per tahun | D15: S.008/013 | E15: THE
... A55: 52 | B55: Standar Kerjasama Kelembagaan | C55: Tersedia mitra kerjasama baru minimal 5 mitra setiap tahun. | D55: S.029/007 | E55: UKSW

Sheet Form Monev UPPS LAMDIK
A1: FORMULIR MONITORING DAN EVALUASI KINERJA LEVEL UNIT PENGELOLA PROGRAM STUDI (LAMDIK)
A3: No. | B3: Nama Standar | C3: Indikator | D3: Kode Indikator | E3: Sumber | F3: Persentase Capaian (tuliskan seberapa besar persentase pencapaian UPPS terhadap setiap indikator, persentase dituliskan berdasarkan penilaian pimpinan PT/evaluasi diri) | G3: Evaluasi Diri (deskripsikan data capaian indikator, dapat berupa data kuantitatif/kualitatif, faktor pendukung/penghambat, masalah yang dihadapi, dan link dokumen bukti) | H3: Tindak Lanjut (tuliskan tindak lanjut yang dilakukan untuk memperbaiki atau meningkatkan capaian indikator)
A4: 1 | B4: Standar Kompetensi Lulusan | C4: Tersedia SK Rektor/ SK Dekan tentang keluaran dan capaian tridharma PT, dan telah disosialisasikan, dilaksanakan, dievaluasi dan ditindaklanjuti. | D4: S.001/015 | E4: LAMDIK
A5: 2 | B5: Standar Dosen dan Tendik | C5: Tersedia dan terimplementasi kebijakan rekrutmen dan seleksi dosen yang mencakup tes kompetensi pedagogik (tes kemampuan bidang studi, peer teaching, dan wawancara); penghargaan, sanksi dan pemutusan hubungan kerja bagi dosen, dilaksanakan secara konsisten dan didokumentasikan secara baik. | D5: S.005/016 | E5: LAMDIK
A6: 3 | B6: Standar Dosen dan Tendik | C6: Tersedia dana dan fasilitas bagi dosen tetap pada program studi kependidikan untuk mengikuti kegiatan keprofesian berkelanjutan seperti studi lanjut, postdoc, academic recharging program (ARP), kursus singkat, magang, pelatihan, sertifikasi, konferensi, seminar, dan lokakarya dalam 3 tahun terakhir. | D6: S.005/019 | E6: LAMDIK
A7: 4 | B7: Standar Dosen dan Tendik | C7: Tersedia dan terimplementasi kebijakan rekrutmen dan tes seleksi tenaga kependidikan secara lengkap, penghargaan, sanksi dan pemutusan hubungan kerja bagi tenaga kependidikan, dilaksanakan secara konsisten dan didokumentasikan dengan baik. | D7: S.005/020 | E7: LAMDIK
A8: 5 | B8: Standar Dosen dan Tendik | C8: Tersedia dana dan fasilitas bagi tenaga kependidikan pada program studi kependidikan untuk mengikuti program pengembangan seperti studi lanjut, diklat, workshop, sertifikasi, magang, atau peningkatan pelayanan umum lainnya (excellent service) yang relevan dengan tugas pokok dan fungsinya. | D8: S.005/021 | E8: LAMDIK
A9: 6 | B9: Standar Dosen dan Tendik | C9: Tersedia dan terimplementasi kebijakan, pedoman dan instrumen survei kepuasan dosen dan tenaga kependidikan terhadap pengelolaan SDM yang dilaksanakan secara rutin setiap tahun, berkesinambungan, hasilnya dilaporkan dan ditindaklanjuti. | D9: S.005/022 | E9: LAMDIK
A10: 7 | B10: Standar Dosen dan Tendik | C10: Tersedia dan terimplementasi kebijakan, pedoman dan instrumen survei kepuasan dosen dan tenaga kependidikan terhadap pengelolaan SDM yang dilaksanakan secara rutin setiap tahun, berkesinambungan, hasilnya dilaporkan dan ditindaklanjuti. | D10: S.005/023 | E10: LAMDIK
A11: 8 | B11: Standar Sarana dan Prasarana Pembelajaran | C11: Terlaksana pengembangan sarana pembelajaran di semua fakultas setiap tahun. | D11: S.006/006 | E11: UKSW
A12: 9 | B12: Standar Sarana dan Prasarana Pembelajaran | C12: Tersedia laboratorium microteaching, lengkap dengan perlengkapan dan peralatan yang mutakhir dan terawat. | D12: S.006/007 | E12: LAMDIK
A13: 10 | B13: Standar Sarana dan Prasarana Pembelajaran | C13: Tersedia laboratorium microteaching, lengkap dengan perlengkapan dan peralatan yang mutakhir dan terawat. | D13: S.006/007 | E13: QS STARS RATING
A14: 11 | B14: Standar Pengelolaan Pembelajaran | C14: Tersedia Rencana Strategis dan Rencana Operasional yang memuat rencana pelaksanaan program pembelajaran | D14: S.007/001 | E14: SN DIKTI
A15: 12 | B15: Standar Pengelolaan Pembelajaran | C15: Terlaksana program pembelajaran sesuai dengan Rencana Strategis dan Rencana Operasional. | D15: S.007/002 | E15: SN DIKTI
... A60: 57 | B60: Standar Kerjasama Kelembagaan | C60: Tersedia mitra kerjasama baru minimal 5 mitra setiap tahun. | D60: S.029/007 | E60: UKSW

Sheet Form Monev UPPS LAMEMBA
A1: FORMULIR MONITORING DAN EVALUASI KINERJA LEVEL UNIT PENGELOLA PROGRAM STUDI (LAMEMBA)
A3: No. | B3: Nama Standar | C3: Indikator | D3: Kode Indikator | E3: Sumber | F3: Persentase Capaian (tuliskan seberapa besar persentase pencapaian UPPS terhadap setiap indikator, persentase dituliskan berdasarkan penilaian pimpinan PT/evaluasi diri) | G3: Evaluasi Diri (deskripsikan data capaian indikator, dapat berupa data kuantitatif/kualitatif, faktor pendukung/penghambat, masalah yang dihadapi, dan link dokumen bukti) | H3: Tindak Lanjut (tuliskan tindak lanjut yang dilakukan untuk memperbaiki atau meningkatkan capaian indikator)
A4: 1 | B4: Standar Dosen dan Tendik | C4: Tersedia dan terimplementasi kebijakan dan pedoman pengembangan karir dosen dan tenaga kependidikan yang terlaksana secara konsisten dan terdokumentasi dengan baik. | D4: S.005/024 | E4: LAMEMBA
A5: 2 | B5: Standar Dosen dan Tendik | C5: Tersedia dan terimplementasi kebijakan dan pedoman pengembangan karir dosen dan tenaga kependidikan yang terlaksana secara konsisten dan terdokumentasi dengan baik. | D5: S.005/025 | E5: LAMEMBA
A6: 3 | B6: Standar Sarana dan Prasarana Pembelajaran | C6: Terlaksana pengembangan sarana pembelajaran di semua fakultas setiap tahun. | D6: S.006/006 | E6: UKSW
A7: 4 | B7: Standar Sarana dan Prasarana Pembelajaran | C7: Tersedia laboratorium microteaching, lengkap dengan perlengkapan dan peralatan yang mutakhir dan terawat. | D7: S.006/007 | E7: QS STARS RATING
A8: 5 | B8: Standar Sarana dan Prasarana Pembelajaran | C8: Tersedia dan terealisasi rencana pengembangan sarana prasarana pembelajaran. | D8: S.006/008 | E8: LAMEMBA
A9: 6 | B9: Standar Pengelolaan Pembelajaran | C9: Tersedia Rencana Strategis dan Rencana Operasional yang memuat rencana pelaksanaan program pembelajaran | D9: S.007/001 | E9: SN DIKTI
A10: 7 | B10: Standar Pengelolaan Pembelajaran | C10: Terlaksana program pembelajaran sesuai dengan Rencana Strategis dan Rencana Operasional. | D10: S.007/002 | E10: SN DIKTI
A11: 8 | B11: Standar Pengelolaan Pembelajaran | C11: Terlaksana penjaminan mutu pengelolaan Program Studi dalam melaksanakan program Pembelajaran secara berkelanjutan dengan sasaran yang sesuai dengan visi dan misi. | D11: S.007/003 | E11: SN DIKTI
A12: 9 | B12: Standar Pengelolaan Pembelajaran | C12: Terlaksana pemantauan dan evaluasi terhadap kegiatan Program Studi dalam melaksanakan kegiatan Pembelajaran. | D12: S.007/004 | E12: SN DIKTI
A13: 10 | B13: Standar Pengelolaan Pembelajaran | C13: Tersedia panduan perencanaan, pelaksanaan, evaluasi, pengawasan, penjaminan mutu, dan pengembangan kegiatan Pembelajaran dan Dosen | D13: S.007/005 | E13: SN DIKTI
A14: 11 | B14: Standar Pengelolaan Pembelajaran | C14: Terlaksana pelaporan kinerja Program Studi dalam menyelenggarakan program Pembelajaran melalui pangkalan data Pendidikan Tinggi. | D14: S.007/006 | E14: SN DIKTI
A15: 12 | B15: Standar Pengelolaan Pembelajaran | C15: Terdokumentasi seluruh proses pembelajaran, mulai dari perencanaan, pelaksanaan, pengendalian, pemantauan dan evaluasi, serta pelaporan kegiatan pembelajaran pada SIIMUT. | D15: S.007/007 | E15: UKSW
... A58: 55 | B58: Standar Kerjasama Kelembagaan | C58: Tersedia mitra kerjasama baru minimal 5 mitra setiap tahun. | D58: S.029/007 | E58: UKSW

Sheet Form Monev UPPS LAMSAMA
A1: FORMULIR MONITORING DAN EVALUASI KINERJA LEVEL UNIT PENGELOLA PROGRAM STUDI (LAMSAMA)
A3: No. | B3: Nama Standar | C3: Indikator | D3: Kode Indikator | E3: Sumber | F3: Persentase Capaian (tuliskan seberapa besar persentase pencapaian UPPS terhadap setiap indikator, persentase dituliskan berdasarkan penilaian pimpinan PT/evaluasi diri) | G3: Evaluasi Diri (deskripsikan data capaian indikator, dapat berupa data kuantitatif/kualitatif, faktor pendukung/penghambat, masalah yang dihadapi, dan link dokumen bukti) | H3: Tindak Lanjut (tuliskan tindak lanjut yang dilakukan untuk memperbaiki atau meningkatkan capaian indikator)
A4: 1 | B4: Standar Sarana dan Prasarana Penelitian | C4: Tersedianya sarana dan prasarana yang relevan dan mutakhir untuk mendukung kegiatan penelitian dan memfasilitasi mahasiswa berkebutuhan khusus. | D4: S.014/001 | E4: APT
A5: 2 | B5: Standar Sarana dan Prasarana PkM | C5: Tersedianya sarana dan prasarana yang relevan dan mutakhir untuk mendukung kegiatan pengabdian kepada masyarakat dan memfasilitasi mahasiswa berkebutuhan khusus. | D5: S.022/001 | E5: APT
A6: 3 | B6: Standar Tata Kelola dan Tata Pamong | C6: Terlaksananya upaya pencapaian akreditasi internasional minimal 8 prodi. | D6: S.026/014 | E6: APT
A7: 4 | B7: Standar Tata Kelola dan Tata Pamong | C7: Terlaksananya upaya pencapaian akreditasi nasional yang mencapai 50 prodi unggul dan sisanya baik sekali | D7: S.026/016 | E7: APT
A8: 5 | B8: Standar Sarana dan Prasarana Pembelajaran | C8: Tersedia laboratorium untuk pelaksanaan pembelajaran dan pengembangan suasana akademik. | D8: S.006/012 | E8: LAMSAMA
A9: 6 | B9: Standar Sarana dan Prasarana Pembelajaran | C9: Tersedia laboratorium microteaching, lengkap dengan perlengkapan dan peralatan yang mutakhir dan terawat. | D9: S.006/007 | E9: QS STARS RATING
A10: 7 | B10: Standar Pengelolaan Pembelajaran | C10: Tersedia Rencana Strategis dan Rencana Operasional yang memuat rencana pelaksanaan program pembelajaran | D10: S.007/001 | E10: SN DIKTI
A11: 8 | B11: Standar Pengelolaan Pembelajaran | C11: Terlaksana program pembelajaran sesuai dengan Rencana Strategis dan Rencana Operasional. | D11: S.007/002 | E11: SN DIKTI
A12: 9 | B12: Standar Pengelolaan Pembelajaran | C12: Terlaksana penjaminan mutu pengelolaan Program Studi dalam melaksanakan program Pembelajaran secara berkelanjutan dengan sasaran yang sesuai dengan visi dan misi. | D12: S.007/003 | E12: SN DIKTI
A13: 10 | B13: Standar Pengelolaan Pembelajaran | C13: Terlaksana pemantauan dan evaluasi terhadap kegiatan Program Studi dalam melaksanakan kegiatan Pembelajaran. | D13: S.007/004 | E13: SN DIKTI
A14: 11 | B14: Standar Pengelolaan Pembelajaran | C14: Tersedia panduan perencanaan, pelaksanaan, evaluasi, pengawasan, penjaminan mutu, dan pengembangan kegiatan Pembelajaran dan Dosen | D14: S.007/005 | E14: SN DIKTI
A15: 12 | B15: Standar Pengelolaan Pembelajaran | C15: Terlaksana pelaporan kinerja Program Studi dalam menyelenggarakan program Pembelajaran melalui pangkalan data Pendidikan Tinggi. | D15: S.007/006 | E15: SN DIKTI
... A51: 48 | B51: Standar Kerjasama Kelembagaan | C51: Tersedia mitra kerjasama baru minimal 5 mitra setiap tahun. | D51: S.029/007 | E51: UKSW

Sheet Form Monev UPPS LAMTEK
A1: FORMULIR MONITORING DAN EVALUASI KINERJA LEVEL UNIT PENGELOLA PROGRAM STUDI (LAMTEK)
A3: No. | B3: Nama Standar | C3: Indikator | D3: Kode Indikator | E3: Sumber | F3: Persentase Capaian (tuliskan seberapa besar persentase pencapaian UPPS terhadap setiap indikator, persentase dituliskan berdasarkan penilaian pimpinan PT/evaluasi diri) | G3: Evaluasi Diri (deskripsikan data capaian indikator, dapat berupa data kuantitatif/kualitatif, faktor pendukung/penghambat, masalah yang dihadapi, dan link dokumen bukti) | H3: Tindak Lanjut (tuliskan tindak lanjut yang dilakukan untuk memperbaiki atau meningkatkan capaian indikator)
A4: 1 | B4: Standar Sarana dan Prasarana Pembelajaran | C4: Terlaksana pengembangan sarana pembelajaran di semua fakultas setiap tahun. | D4: S.006/006 | E4: UKSW
A5: 2 | B5: Standar Sarana dan Prasarana Pembelajaran | C5: Tersedia laboratorium microteaching, lengkap dengan perlengkapan dan peralatan yang mutakhir dan terawat. | D5: S.006/007 | E5: QS STARS RATING
A6: 3 | B6: Standar Pengelolaan Pembelajaran | C6: Tersedia Rencana Strategis dan Rencana Operasional yang memuat rencana pelaksanaan program pembelajaran | D6: S.007/001 | E6: SN DIKTI
A7: 4 | B7: Standar Pengelolaan Pembelajaran | C7: Terlaksana program pembelajaran sesuai dengan Rencana Strategis dan Rencana Operasional. | D7: S.007/002 | E7: SN DIKTI
A8: 5 | B8: Standar Pengelolaan Pembelajaran | C8: Terlaksana penjaminan mutu pengelolaan Program Studi dalam melaksanakan program Pembelajaran secara berkelanjutan dengan sasaran yang sesuai dengan visi dan misi. | D8: S.007/003 | E8: SN DIKTI
A9: 6 | B9: Standar Pengelolaan Pembelajaran | C9: Terlaksana pemantauan dan evaluasi terhadap kegiatan Program Studi dalam melaksanakan kegiatan Pembelajaran. | D9: S.007/004 | E9: SN DIKTI
A10: 7 | B10: Standar Pengelolaan Pembelajaran | C10: Tersedia panduan perencanaan, pelaksanaan, evaluasi, pengawasan, penjaminan mutu, dan pengembangan kegiatan Pembelajaran dan Dosen | D10: S.007/005 | E10: SN DIKTI
A11: 8 | B11: Standar Pengelolaan Pembelajaran | C11: Terlaksana pelaporan kinerja Program Studi dalam menyelenggarakan program Pembelajaran melalui pangkalan data Pendidikan Tinggi. | D11: S.007/006 | E11: SN DIKTI
A12: 9 | B12: Standar Pengelolaan Pembelajaran | C12: Terdokumentasi seluruh proses pembelajaran, mulai dari perencanaan, pelaksanaan, pengendalian, pemantauan dan evaluasi, serta pelaporan kegiatan pembelajaran pada SIIMUT. | D12: S.007/007 | E12: UKSW
A13: 10 | B13: Standar Pengelolaan Pembelajaran | C13: Tersedia dan terselenggara sistem aduan akademik untuk mahasiswa untuk menyelesaikan masalah-masalah akademik dengan tingkat persentase penyelesaian masalah mencapai 100% | D13: S.007/008 | E13: UKSW
A14: 11 | B14: Standar Pembiayaan Pembelajaran | C14: Tercapainya jumlah pendapatan institusi pada bidang pendidikan minimal sebesar Rp20 juta per mahasiswa per tahun | D14: S.008/013 | E14: THE
A15: 12 | B15: Standar Penilaian Penelitian | C15: Tersedia reviewer penelitian tingkat nasional yang tersertifikasi minimal 1 orang per fakultas. | D15: S.012/004 | E15: UKSW
... A51: 48 | B51: Standar Kerjasama Kelembagaan | C51: Tersedia mitra kerjasama baru minimal 5 mitra setiap tahun. | D51: S.029/007 | E51: UKSW

Sheet Form Monev PS BAN-PT
A1: FORMULIR MONITORING DAN EVALUASI KINERJA LEVEL PROGRAM STUDI (BAN-PT)
A3: No. | B3: Nama Standar | C3: Indikator | D3: Kode Indikator | E3: Sumber | F3: Persentase Capaian (tuliskan seberapa besar persentase pencapaian prodi terhadap setiap indikator, persentase dituliskan berdasarkan penilaian pimpinan PT/evaluasi diri) | G3: Evaluasi Diri (deskripsikan data capaian indikator, dapat berupa data kuantitatif/kualitatif, faktor pendukung/penghambat, masalah yang dihadapi, dan link dokumen bukti) | H3: Tindak Lanjut (tuliskan tindak lanjut yang dilakukan untuk memperbaiki atau meningkatkan capaian indikator)
A4: 1 | B4: Standar Kompetensi Lulusan | C4: Tercapai target 100% mahasiswa yang lulus telah memenuhi KKM minimal 1.000 poin. | D4: S.001/013 | E4: UKSW
A5: 2 | B5: Standar Isi Pembelajaran | C5: Tersedianya matakuliah program studi yang memungkinkan diambil oleh mahasiswa dari luar program studi di dalam UKSW, mahasiswa dari luar program studi di luar UKSW, dan mahasiswa asing. | D5: S.002/008 | E5: UKSW
A6: 3 | B6: Standar Proses Pembelajaran | C6: Terlaksana Doa Pembukaan pada perkuliahan jam semua perkuliahan yang dilaksanakan pada jam pertama dan Doa Penutupan pada semua perkuliahan yang dilaksanakan pada jam terakhir setiap hari. | D6: S.003/017 | E6: UKSW
A7: 4 | B7: Standar Proses Pembelajaran | C7: Terlaksananya kegiatan belajar mahasiswa yang dilakukan di luar kelas. | D7: S.003/026 | E7: QS STARS RATING
A8: 5 | B8: Standar Proses Pembelajaran | C8: Terlaksana kegiatan pembelajaran daring dengan baik dan lancar. | D8: S.003/028 | E8: QS STARS RATING
A9: 6 | B9: Standar Penilaian Pembelajaran | C9: Terlaksana penilaian dengan model PAN (Penilaian Acuan Norma) dan PAP (Penilaian Acuan Patokan) | D9: S.004/007 | E9: UKSW
A10: 7 | B10: Standar Penilaian Pembelajaran | C10: Terlaksananya survei kepuasan mahasiswa terhadap layanan mengajar dosen yang lengkap, antara lain: 1) Menggunakan instrumen yang valid dan mudah digunakan; 2) Dilaksanakan setiap semester dan terekam secara lengkap; 3) Dianalisis dengan metode ilmiah yang tepat untuk pengambilan keputusan; 4) Dilakukan review terhadap proses dan hasil survei; 5) Ditindaklanjuti hasilnya; dan 6) Dipublikasikan hasilnya agar mudah diakses para pemangku kepentingan. | D10: S.004/009 | E10: QS STARS RATING
A11: 8 | B11: Standar Penilaian Pembelajaran | C11: Terlaksananya survei kepuasan mahasiswa terhadap layanan mengajar dosen yang lengkap, antara lain: 1) Menggunakan instrumen yang valid dan mudah digunakan; 2) Dilaksanakan setiap semester dan terekam secara lengkap; 3) Dianalisis dengan metode ilmiah yang tepat untuk pengambilan keputusan; 4) Dilakukan review terhadap proses dan hasil survei; 5) Ditindaklanjuti hasilnya; dan 6) Dipublikasikan hasilnya agar mudah diakses para pemangku kepentingan. | D11: S.004/009 | E11: THE
A12: 9 | B12: Standar Dosen dan Tendik | C12: Tercapainya kecukupan jumlah dosen Doktor untuk memenuhi rasio jumlah dosen Doktor terhadap mahasiswa Sarjana minimal 1:40 | D12: S.005/031 | E12: THE
A13: 10 | B13: Standar Sarana dan Prasarana Pembelajaran | C13: Tersedia koleksi perpustakaan yang sesuai dengan bidang kompetensi program studi. | D13: S.006/005 | E13: QS STARS RATING
A14: 11 | B14: Standar Sarana dan Prasarana Pembelajaran | C14: Tersedia koleksi perpustakaan yang sesuai dengan bidang kompetensi program studi. | D14: S.006/005 | E14: UKSW
A15: 12 | B15: Standar Pengelolaan Pembelajaran | C15: Tersedia pusat pembelajaran akademik yang dapat dimanfaatkan oleh mahasiswa | D15: S.007/009 | E15: QS STARS RATING
... A33: 30 | B33: Admisi Kemahasiswaan | C33: Terlaksananya pembatasan penerimaan mahasiswa transfer maksimal sebanyak 5% dari keseluruhan jumlah mahasiswa program studi, untuk semua program studi. | D33: S.027/008 | E33: UKSW

Sheet Form Monev PS LAM INFOKOM
A1: FORMULIR MONITORING DAN EVALUASI KINERJA LEVEL PROGRAM STUDI (LAM INFOKOM)
A3: No. | B3: Nama Standar | C3: Indikator | D3: Kode Indikator | E3: Sumber | F3: Persentase Capaian (tuliskan seberapa besar persentase pencapaian prodi terhadap setiap indikator, persentase dituliskan berdasarkan penilaian pimpinan PT/evaluasi diri) | G3: Evaluasi Diri (deskripsikan data capaian indikator, dapat berupa data kuantitatif/kualitatif, faktor pendukung/penghambat, masalah yang dihadapi, dan link dokumen bukti) | H3: Tindak Lanjut (tuliskan tindak lanjut yang dilakukan untuk memperbaiki atau meningkatkan capaian indikator)
A4: 1 | B4: Standar Kompetensi Lulusan | C4: Tercapai target 100% mahasiswa yang lulus telah memenuhi KKM minimal 1.000 poin. | D4: S.001/013 | E4: UKSW
A5: 2 | B5: Standar Kompetensi Lulusan | C5: Tersedia karya dosen dan/atau mahasiswa yang dihasilkan melalui proses pembelajaran yang mendapat HKI. | D5: S.001/014 | E5: LAM INFOKOM
A6: 3 | B6: Standar Isi Pembelajaran | C6: Tersedianya matakuliah program studi yang memungkinkan diambil oleh mahasiswa dari luar program studi di dalam UKSW, mahasiswa dari luar program studi di luar UKSW, dan mahasiswa asing. | D6: S.002/008 | E6: UKSW
A7: 4 | B7: Standar Proses Pembelajaran | C7: Terlaksana Doa Pembukaan pada perkuliahan jam semua perkuliahan yang dilaksanakan pada jam pertama dan Doa Penutupan pada semua perkuliahan yang dilaksanakan pada jam terakhir setiap hari. | D7: S.003/017 | E7: UKSW
A8: 5 | B8: Standar Proses Pembelajaran | C8: Tersedia dan terimplementasi mekanisme proses penyelesaian tugas akhir/ tesis/ disertasi. | D8: S.003/018 | E8: LAM INFOKOM
A9: 6 | B9: Standar Proses Pembelajaran | C9: Terlaksananya kegiatan belajar mahasiswa yang dilakukan di luar kelas. | D9: S.003/026 | E9: QS STARS RATING
A10: 7 | B10: Standar Proses Pembelajaran | C10: Terlaksana kegiatan pembelajaran daring dengan baik dan lancar. | D10: S.003/028 | E10: QS STARS RATING
A11: 8 | B11: Standar Penilaian Pembelajaran | C11: Terlaksana penilaian dengan model PAN (Penilaian Acuan Norma) dan PAP (Penilaian Acuan Patokan) | D11: S.004/007 | E11: UKSW
A12: 9 | B12: Standar Penilaian Pembelajaran | C12: Terlaksananya survei kepuasan mahasiswa terhadap layanan mengajar dosen yang lengkap, antara lain: 1) Menggunakan instrumen yang valid dan mudah digunakan; 2) Dilaksanakan setiap semester dan terekam secara lengkap; 3) Dianalisis dengan metode ilmiah yang tepat untuk pengambilan keputusan; 4) Dilakukan review terhadap proses dan hasil survei; 5) Ditindaklanjuti hasilnya; dan 6) Dipublikasikan hasilnya agar mudah diakses para pemangku kepentingan. | D12: S.004/009 | E12: QS STARS RATING
A13: 10 | B13: Standar Penilaian Pembelajaran | C13: Terlaksananya survei kepuasan mahasiswa terhadap layanan mengajar dosen yang lengkap, antara lain: 1) Menggunakan instrumen yang valid dan mudah digunakan; 2) Dilaksanakan setiap semester dan terekam secara lengkap; 3) Dianalisis dengan metode ilmiah yang tepat untuk pengambilan keputusan; 4) Dilakukan review terhadap proses dan hasil survei; 5) Ditindaklanjuti hasilnya; dan 6) Dipublikasikan hasilnya agar mudah diakses para pemangku kepentingan. | D13: S.004/009 | E13: THE
A14: 11 | B14: Standar Dosen dan Tendik | C14: Tercapainya kecukupan jumlah dosen Doktor untuk memenuhi rasio jumlah dosen Doktor terhadap mahasiswa Sarjana minimal 1:40 | D14: S.005/031 | E14: THE
A15: 12 | B15: Standar Sarana dan Prasarana Pembelajaran | C15: Tersedia koleksi perpustakaan yang sesuai dengan bidang kompetensi program studi. | D15: S.006/005 | E15: QS STARS RATING
... A37: 34 | B37: Admisi Kemahasiswaan | C37: Terlaksananya pembatasan penerimaan mahasiswa transfer maksimal sebanyak 5% dari keseluruhan jumlah mahasiswa program studi, untuk semua program studi. | D37: S.027/008 | E37: UKSW

Sheet Form Monev PS LAM PTKES NERS
A1: FORMULIR MONITORING DAN EVALUASI KINERJA LEVEL PROGRAM STUDI (LAM PT-KES NERS)
A3: No. | B3: Nama Standar | C3: Indikator | D3: Kode Indikator | E3: Sumber | F3: Persentase Capaian (tuliskan seberapa besar persentase pencapaian prodi terhadap setiap indikator, persentase dituliskan berdasarkan penilaian pimpinan PT/evaluasi diri) | G3: Evaluasi Diri (deskripsikan data capaian indikator, dapat berupa data kuantitatif/kualitatif, faktor pendukung/penghambat, masalah yang dihadapi, dan link dokumen bukti) | H3: Tindak Lanjut (tuliskan tindak lanjut yang dilakukan untuk memperbaiki atau meningkatkan capaian indikator)
A4: 1 | B4: Standar Kompetensi Lulusan | C4: Tercapai target 100% mahasiswa yang lulus telah memenuhi KKM minimal 1.000 poin. | D4: S.001/013 | E4: UKSW
A5: 2 | B5: Standar Kompetensi Lulusan | C5: Tercapainya target 80% lulusan Ners mampu lulus Uji Kompetensi Ners Indonesia (UKNI) dalam tiga tahun terakhir. | D5: S.001/018 | E5: LAM PT-KES NERS
A6: 3 | B6: Standar Kompetensi Lulusan | C6: Tercapainya target 80% lulusan Ners mampu lulus Uji Kompetensi Ners Indonesia Objective Structured Clinical Examination (UKNIOSCE) dalam tiga tahun terakhir. | D6: S.001/019 | E6: LAM PT-KES NERS
A7: 4 | B7: Standar Isi Pembelajaran | C7: Tersedianya matakuliah program studi yang memungkinkan diambil oleh mahasiswa dari luar program studi di dalam UKSW, mahasiswa dari luar program studi di luar UKSW, dan mahasiswa asing. | D7: S.002/008 | E7: UKSW
