Workbook
Name diploma: #REF!
Name diploma: #REF!

Sheet Isian Prodi
A1: ISIAN PROGRAM STUDI
A3: PETUNJUK PENGISIAN: SEL YANG DIISI PRODI HANYA YANG BERWARNA KUNING
A5: Nama Prodi : | C5: Prodi A
A6: Nama UPPS : | C6: Fakultas/Departemen A
A7: Jenis prodi : (1 : Prodi sains teknologi; 2 : Prodi sosial humaniora)
A8: Jumlah kebutuhan lulusan : 1: Tinggi; 2: Rendah.
A10: Tabel 1 Jumlah Kerjasama Tridharma
A11: Tahun Akademik | B11: Tingkat | C11: Pendidikan | D11: Penelitian | E11: Pengabdian kepada Masyarakat
A12: 1 | B12: 2 | C12: 3 | D12: 4 | E12: 5
A13: TS-2 | B13: Internasional
A14: TS-1
A15: TS
A16: Jumlah | C16: =SUM(C13:C15) -> 0 | D16: =SUM(D13:D15) -> 0 | E16: =SUM(E13:E15) -> 0
A17: TS-2 | B17: Nasional
A18: TS-1
A19: TS
A20: Jumlah | C20: =SUM(C17:C19) -> 0 | D20: =SUM(D17:D19) -> 0 | E20: =SUM(E17:E19) -> 0
A21: TS-2 | B21: Lokal/Wilayah
A22: TS-1
A23: TS
A24: Jumlah | C24: =SUM(C21:C23) -> 0 | D24: =SUM(D21:D23) -> 0 | E24: =SUM(E21:E23) -> 0
A26: Tabel 2 Seleksi Mahasiswa Baru
A27: Tahun Akademik | B27: Daya Tampung | C27: Jumlah Calon Mahasiswa | E27: Jumlah Mahasiswa Baru | G27: Jumlah Mahasiswa Aktif
C28: Pendaftar | D28: Lulus Seleksi | E28: Reguler | F28: Transfer*) | G28: Reguler | H28: Transfer*)
A29: 1 | B29: 2 | C29: 3 | D29: 4 | E29: 5 | F29: 6 | G29: 7 | H29: 8
A30: TS-4
A31: TS-3
A32: TS-2
A33: TS-1
A34: TS
A35: Jumlah | B35: =SUM(B30:B34) -> 0 | C35: =SUM(C30:C34) -> 0 | D35: =SUM(D30:D34) -> 0 | E35: =SUM(E30:E34) -> 0 | F35: =SUM(F30:F34) -> 0 | G35: =SUM(G34:H34) -> 0
A37: Tabel 3 Jumlah Mahasiswa Asing
A38: Tahun Akademik | B38: Jumlah Mahasiswa Aktif | C38: Jumlah Mahasiswa Asing
A39: 1 | B39: 2 | C39: 3
A40: TS-4 | B40: =SUM(G30:H30) -> 0
A41: TS-3 | B41: =SUM(G31:H31) -> 0
A42: TS-2 | B42: =SUM(G32:H32) -> 0
A43: TS-1 | B43: =SUM(G33:H33) -> 0
A44: TS | B44: =SUM(G34:H34) -> 0
A45: Jumlah | B45: =G35 -> 0 | C45: =SUM(C40:C44) -> 0
...

Sheet Kertas Kerja
A1: KERTAS KERJA AUDIT MUTU INTERNAL
A2: PROGRAM SARJANA
A4: PETUNJUK PENGISIAN: SEL YANG DIISI PRODI HANYA YANG BERWARNA KUNING, SEL YANG DIISI AUDITOR MUTU INTERNAL HANYA YANG BERWARNA BIRU
A6: NO. | B6: ELEMEN | C6: INDIKATOR DAN PENILAIAN | E6: DOKUMEN BUKTI | F6: EVALUASI DIRI PROGRAM STUDI | G6: MANAJEMEN RISIKO | K6: SKOR AUDITOR MUTU | L6: DESKRIPSI TEMUAN AUDITOR MUTU INTERNAL | M6: REKOMENDASI AUDITOR MUTU INTERNAL
G7: IDENTIFIKASI RISIKO | H7: TINGKAT KEMUNGKINAN | I7: SKALA DAMPAK | J7: LEVEL RISIKO
A8: 1 | B8: A | C8: Kondisi Eksternal Konsistensi dengan hasil analisis SWOT dan/atau analisis lain serta rencana pengembangan ke depan. | E8: (1) Laporan yang berisi analisis internal dan eksternal Fakultas/Departemen yang lengkap (identifikasi faktor, penentuan posisi strategis, perumusan strategi dan arah pengembangan strategik) bisa menggunakan Analisis SWOT dan/atau analisis lainnya. (2) Rencana stategis fakultas/ departemen yang disahkan dengan SK Rektor. | F8: Deskripsi dan penjelasan tentang indikator yang terkait | G8: Deskripsi identifikasi risiko tentang indikator yang terkait | H8: C | I8: 4 | J8: =IF((IF(OR((H8&"."&I8)=$R$8,(H8&"."&I8)=$S$8,(H8&"."&I8)=$T$8,(H8&"."&I8)=$U$8,(H8&"."&I8)=$V$8,(H8&"."&I8)=$W$8),1,0))=1,"EKSTREM",IF((IF(OR((H8&"."&I8)=$R$9,(H8&"."&I8)=$S$9,(H8&"."&I8)=$T$9,(H8&"."&I8)=$U$9,(H8&"."&I8)=$V$9,(H8&"."&I8)=$W$9,(H8&"."&I8)=$X$9),1,0))=1,"TINGGI",IF((IF(OR((H8&"."&I8)=$R$10,(H8&"."&I8)=$S$10,(H8&"."&I8)=$T$10,(H8&"."&I8)=$U$10,(H8&"."&I8)=$V$10,(H8&"."&I8)=$W$10),1,0))=1,"MODERAT",IF((IF(OR((H8&"."&I8)=$R$11,(H8&"."&I8)=$S$11,(H8&"."&I8)=$T$11,(H8&"."&I8)=$U$11,(H8&"."&I8)=$V$11,(H8&"."&I8)=$W$11),1,0))=1,"RENDAH","-")))) -> TINGGI | K8: 3 | L8: deskripsi test | M8: rekomendasi test | P8: E | Q8: EKSTREM | R8: E.4 | S8: E.5 | T8: D.4 | U8: D.5 | V8: C.5 | W8: B.5
C9: 4 | D9: Unit Pengelola Program Studi (UPPS) mampu: 1) mengidentifikasi kondisi lingkungan dan industri yang relevan secara komprehensif dan strategis, 2) menetapkan posisi relatif program studi terhadap lingkungannya, 3) menggunakan hasil identifikasi dan posisi yang ditetapkan untuk melakukan analisis (SWOT/metoda analisis lain yang relevan) untuk pengembangan program studi, dan 4) merumuskan strategi pengembangan program studi yang berkesesuaian untuk menghasilkan program-program pengembangan alternatif yang tepat. | P9: T | Q9: TINGGI | R9: E.3 | S9: D.3 | T9: C.4 | U9: C.3 | V9: B.4 | W9: A.5 | X9: A.4
C10: 3 | D10: Unit Pengelola Program Studi (UPPS) mampu: 1) mengidentifikasi kondisi lingkungan dan industri yang relevan secara komprehensif, 2) menetapkan posisi relatif program studi terhadap lingkungannya, dan 3) menggunakan hasil identifikasi dan posisi yang ditetapkan untuk melakukan analisis (SWOT/metoda analisis lain yang relevan) untuk pengembangan program studi. | P10: M | Q10: MODERAT | R10: E.1 | S10: E.2 | T10: D.2 | U10: C.2 | V10: B.3 | W10: A.3
C11: 2 | D11: Unit Pengelola Program Studi (UPPS) mampu: 1) mengidentifikasi kondisi lingkungan dan industri yang relevan, dan 2) menetapkan posisi relatif program studi terhadap lingkungannya. | P11: R | Q11: RENDAH | R11: D.1 | S11: C.1 | T11: B.1 | U11: B.2 | V11: A.2 | W11: A.1
C12: 1 | D12: Unit Pengelola Program Studi (UPPS) kurang mampu: 1) mengidentifikasi kondisi lingkungan dan industri yang relevan, dan 2) menetapkan posisi relatif program studi terhadap lingkungannya.
C13: 0 | D13: Unit Pengelola Program Studi (UPPS) tidak mampu: 1) mengidentifikasi kondisi lingkungan dan industri yang relevan, dan 2) menetapkan posisi relatif program studi terhadap lingkungannya.
C14: Skor | J14: =IF(OR(ISBLANK(J8),J8<0,J8>4),0,J8) -> 0 | K14: =IF(OR(ISBLANK(K8),K8<0,K8>4),0,K8) -> 3
A16: 2 | B16: B | C16: Keserbacakupan informasi dalam profil dan konsistensi antara profil dengan data dan informasi yang disampaikan pada masing-masing kriteria, serta menunjukkan iklim yang kondusif untuk pengembangan dan reputasi sebagai rujukan di bidang keilmuannya. | E16: (1)Profil/Katalog fakultas/departemen yang berisi antara lain visi dan misi, dosen, kurikulum, kegiatan kemahasiswaan, kegiatan akademik dan kegiatan pendukung lainnya dalam bentuk softcopy maupun hardcopy. (2)Profil/Katalog program studi yang berisi antara lain visi dan misi, dosen, kurikulum, kegiatan kemahasiswaan, kegiatan akademik dan kegiatan pendukung lainnya dalam bentuk softcopy maupun hardcopy. (3) Bukti kerjasama dengan asosiasi/profesi yang terkait dengan program studi/fakultas/departemen. | F16: Deskripsi dan penjelasan tentang indikator yang terkait | G16: Deskripsi identifikasi risiko tentang indikator yang terkait | H16: E | I16: 1 | J16: =IF((IF(OR((H16&"."&I16)=$R$8,(H16&"."&I16)=$S$8,(H16&"."&I16)=$T$8,(H16&"."&I16)=$U$8,(H16&"."&I16)=$V$8,(H16&"."&I16)=$W$8),1,0))=1,"EKSTREM",IF((IF(OR((H16&"."&I16)=$R$9,(H16&"."&I16)=$S$9,(H16&"."&I16)=$T$9,(H16&"."&I16)=$U$9,(H16&"."&I16)=$V$9,(H16&"."&I16)=$W$9,(H16&"."&I16)=$X$9),1,0))=1,"TINGGI",IF((IF(OR((H16&"."&I16)=$R$10,(H16&"."&I16)=$S$10,(H16&"."&I16)=$T$10,(H16&"."&I16)=$U$10,(H16&"."&I16)=$V$10,(H16&"."&I16)=$W$10),1,0))=1,"MODERAT",IF((IF(OR((H16&"."&I16)=$R$11,(H16&"."&I16)=$S$11,(H16&"."&I16)=$T$11,(H16&"."&I16)=$U$11,(H16&"."&I16)=$V$11,(H16&"."&I16)=$W$11),1,0))=1,"RENDAH","-")))) -> MODERAT | K16: 0 | L16: Deskripsi temuan auditor mutu internal tentang indikator yang terkait | M16: Rekomendasi auditor mutu internal berkaitan dengan hasil temuan
C17: 4 | D17: Profil UPPS: 1) menunjukkan keserbacakupan informasi yang jelas dan konsisten dengan data dan informasi yang disampaikan pada masing-masing kriteria, 2) menggambarkan keselarasan dengan substansi keilmuan program studi. 3) menunjukkan iklim yang kondusif untuk pengembangan keilmuan program studi. 4) menunjukkan reputasi sebagai rujukan di bidang keilmuannya.
C18: 3 | D18: Profil UPPS: 1) menunjukkan keserbacakupan informasi yang jelas dan konsisten dengan data dan informasi yang disampaikan pada masing-masing kriteria, 2) menggambarkan keselarasan dengan substansi keilmuan program studi. 3) menunjukkan iklim yang kondusif untuk pengembangan keilmuan program studi.
C19: 2 | D19: Profil UPPS: 1) menunjukkan keserbacakupan informasi yang jelas dengan data dan informasi yang disampaikan pada masing-masing kriteria, 2) menggambarkan keselarasan dengan substansi keilmuan program studi.
C20: 1 | D20: Profil UPPS: 1) kurang menunjukkan keserbacakupan informasi yang jelas dengan data dan informasi yang disampaikan pada masing-masing kriteria, 2) kurang menggambarkan keselarasan dengan substansi keilmuan program studi.
C21: 0 | D21: Profil UPPS tidak menunjukkan keserbacakupan informasi yang jelas dengan data dan informasi yang disampaikan pada masing-masing kriteria.
C22: Skor | K22: =IF(OR(ISBLANK(K16),K16<0,K16>4),0,K16) -> 0
A24: 3 | B24: C Kriteria C.1 Visi, Misi, Tujuan dan Strategi C.1.4 Indikator Kinerja Utama | C24: Kesesuaian Visi, Misi, Tujuan dan Strategi (VMTS) Unit Pengelola Program Studi (UPPS) terhadap VMTS Perguruan Tinggi (PT) dan visi keilmuan Program Studi (PS) yang dikelolanya. | E24: (1) SK Satgas penyusunan/review VMTS (2) Laporan penyusunan VMTS fakultas/departemen yang memuat latar belakang, tujuan, rasional, mekanisme dan kesesuaian dengan VMTS UKSW (3) SK Pengesahan VMTS fakultas/departemen dan program studi yang menunjukkan keunikan program studi (4) Dokumen perumusan capaian pembelajaran dan peta kurikulum yang menunjukkan kesesuaian dengan keunikan program studi (5) Dokumen SPMI Fakultas dan Universitas (6) Renstra/Road Map/Peta riset dan pengabdian masyarakat yang menunjukkan kesesuaian dengan VMTS program studi | F24: Deskripsi dan penjelasan tentang indikator yang terkait | G24: Deskripsi identifikasi risiko tentang indikator yang terkait | H24: E | I24: 4 | J24: =IF((IF(OR((H24&"."&I24)=$R$8,(H24&"."&I24)=$S$8,(H24&"."&I24)=$T$8,(H24&"."&I24)=$U$8,(H24&"."&I24)=$V$8,(H24&"."&I24)=$W$8),1,0))=1,"EKSTREM",IF((IF(OR((H24&"."&I24)=$R$9,(H24&"."&I24)=$S$9,(H24&"."&I24)=$T$9,(H24&"."&I24)=$U$9,(H24&"."&I24)=$V$9,(H24&"."&I24)=$W$9,(H24&"."&I24)=$X$9),1,0))=1,"TINGGI",IF((IF(OR((H24&"."&I24)=$R$10,(H24&"."&I24)=$S$10,(H24&"."&I24)=$T$10,(H24&"."&I24)=$U$10,(H24&"."&I24)=$V$10,(H24&"."&I24)=$W$10),1,0))=1,"MODERAT",IF((IF(OR((H24&"."&I24)=$R$11,(H24&"."&I24)=$S$11,(H24&"."&I24)=$T$11,(H24&"."&I24)=$U$11,(H24&"."&I24)=$V$11,(H24&"."&I24)=$W$11),1,0))=1,"RENDAH","-")))) -> EKSTREM | K24: 0 | L24: Deskripsi temuan auditor mutu internal tentang indikator yang terkait | M24: Rekomendasi auditor mutu internal berkaitan dengan hasil temuan
C25: 4 | D25: UPPS memiliki: 1) visi yang mencerminkan visi perguruan tinggi dan memayungi visi keilmuan terkait keunikan program studi serta didukung data konsistensi implementasinya, 2) misi, tujuan, dan strategi yang searah dan bersinerji dengan misi, tujuan, dan strategi perguruan tinggi serta mendukung pengembangan program studi dengan data konsistensi implementasinya.
C26: 3 | D26: UPPS memiliki: 1) visi yang mencerminkan visi perguruan tinggi dan memayungi visi keilmuan terkait keunikan program studi, 2) misi, tujuan, dan strategi yang searah dan bersinerji dengan misi, tujuan, dan strategi perguruan tinggi serta mendukung pengembangan program studi.
C27: 2 | D27: UPPS memiliki: 1) visi yang mencerminkan visi perguruan tinggi dan memayungi visi keilmuan terkait program studi, 2) misi, tujuan, dan strategi yang searah dengan misi, tujuan, dan strategi perguruan tinggi serta mendukung pengembangan program studi.
C28: 1 | D28: UPPS memiliki: 1) visi yang mencerminkan visi perguruan tinggi namun tidak memayungi visi keilmuan terkait program studi, 2) misi, tujuan, dan strategi kurang searah dengan misi, tujuan sasaran, dan strategi perguruan tinggi serta kurang mendukung pengembangan program studi.
C29: 0 | D29: UPPS memiliki misi, tujuan, dan strategi yang tidak terkait dengan strategi perguruan tinggi dan pengembangan program studi.
C30: Skor | K30: =IF(OR(ISBLANK(K24),K24<0,K24>4),0,K24) -> 0
A32: 4 | C32: Mekanisme dan keterlibatan pemangku kepentingan dalam penyusunan VMTS UPPS. | E32: (1) Standar VMTS fakultas/departemen (2) Prosedur (SOP) penyusunan dan pengkajian VMTS (3) Laporan penyusunan VMTS yang memuat pelibatan pemangku kepentingan internal dan eksternal (4) Berita acara/dokumentasi/notulen keterlibatan pihak internal (dosen, tendik dan pejabat struktural) dalam rapat dengan agenda penyusunan/review VMTS, serta pihak eksternal (alumni, pengguna, asosiasi, pakar, industri/organisasi) yang sesuai dengan bidang ilmu. | F32: Deskripsi dan penjelasan tentang indikator yang terkait | G32: Deskripsi identifikasi risiko tentang indikator yang terkait | H32: E | I32: 1 | J32: =IF((IF(OR((H32&"."&I32)=$R$8,(H32&"."&I32)=$S$8,(H32&"."&I32)=$T$8,(H32&"."&I32)=$U$8,(H32&"."&I32)=$V$8,(H32&"."&I32)=$W$8),1,0))=1,"EKSTREM",IF((IF(OR((H32&"."&I32)=$R$9,(H32&"."&I32)=$S$9,(H32&"."&I32)=$T$9,(H32&"."&I32)=$U$9,(H32&"."&I32)=$V$9,(H32&"."&I32)=$W$9,(H32&"."&I32)=$X$9),1,0))=1,"TINGGI",IF((IF(OR((H32&"."&I32)=$R$10,(H32&"."&I32)=$S$10,(H32&"."&I32)=$T$10,(H32&"."&I32)=$U$10,(H32&"."&I32)=$V$10,(H32&"."&I32)=$W$10),1,0))=1,"MODERAT",IF((IF(OR((H32&"."&I32)=$R$11,(H32&"."&I32)=$S$11,(H32&"."&I32)=$T$11,(H32&"."&I32)=$U$11,(H32&"."&I32)=$V$11,(H32&"."&I32)=$W$11),1,0))=1,"RENDAH","-")))) -> MODERAT | K32: 0 | L32: Deskripsi temuan auditor mutu internal tentang indikator yang terkait | M32: Rekomendasi auditor mutu internal berkaitan dengan hasil temuan
C33: 4 | D33: Ada mekanisme dalam penyusunan dan penetapan visi, misi, tujuan dan strategi yang terdokumentasi serta ada keterlibatan semua pemangku kepentingan internal (dosen, mahasiswa dan tenaga kependidikan) dan eksternal (lulusan, pengguna lulusan dan pakar/mitra/organisasi profesi/pemerintah).
C34: 3 | D34: Ada mekanisme dalam penyusunan dan penetapan visi, misi, tujuan dan strategi yang terdokumentasi serta ada keterlibatan pemangku kepentingan internal (dosen, mahasiswa dan tenaga kependidikan) dan pemangku kepentingan eksternal (lulusan dan pengguna lulusan).
C35: 2 | D35: Ada mekanisme dalam penyusunan dan penetapan visi, misi, tujuan dan strategi yang terdokumentasi serta ada keterlibatan pemangku kepentingan internal (dosen dan mahasiswa) dan pemangku kepentingan eksternal (lulusan).
C36: 1 | D36: Ada mekanisme dalam penyusunan dan penetapan visi, misi, tujuan dan strategi yang terdokumentasi namun tidak melibatkan pemangku kepentingan.
C37: 0 | D37: Tidak ada mekanisme dalam penyusunan dan penetapan visi, misi, tujuan dan strategi.
C38: Skor | K38: =IF(OR(ISBLANK(K32),K32<0,K32>4),0,K32) -> 0
A40: 5 | C40: Strategi pencapaian tujuan disusun berdasarkan analisis yang sistematis, serta pada pelaksanaannya dilakukan pemantauan dan evaluasi yang ditindaklanjuti. | E40: (1) Laporan yang berisi analisis internal dan eksternal Fakultas/Departemen yang lengkap (identifikasi faktor, penentuan posisi strategis, perumusan strategi dan arah pengembangan strategik) bisa menggunakan Analisis SWOT dan/atau analisis lainnya. (2) Rencana strategis fakultas/departemen yang disahkan dengan SK Rektor. (3) Rencana operasional fakultas/departemen yang disahkan oleh Rektor/Dekan. (4) Laporan Evaluasi Diri (laporan Dies/laporan Raker) tahunan fakultas/departemen. | F40: Deskripsi dan penjelasan tentang indikator yang terkait | G40: Deskripsi identifikasi risiko tentang indikator yang terkait | H40: E | I40: 1 | J40: =IF((IF(OR((H40&"."&I40)=$R$8,(H40&"."&I40)=$S$8,(H40&"."&I40)=$T$8,(H40&"."&I40)=$U$8,(H40&"."&I40)=$V$8,(H40&"."&I40)=$W$8),1,0))=1,"EKSTREM",IF((IF(OR((H40&"."&I40)=$R$9,(H40&"."&I40)=$S$9,(H40&"."&I40)=$T$9,(H40&"."&I40)=$U$9,(H40&"."&I40)=$V$9,(H40&"."&I40)=$W$9,(H40&"."&I40)=$X$9),1,0))=1,"TINGGI",IF((IF(OR((H40&"."&I40)=$R$10,(H40&"."&I40)=$S$10,(H40&"."&I40)=$T$10,(H40&"."&I40)=$U$10,(H40&"."&I40)=$V$10,(H40&"."&I40)=$W$10),1,0))=1,"MODERAT",IF((IF(OR((H40&"."&I40)=$R$11,(H40&"."&I40)=$S$11,(H40&"."&I40)=$T$11,(H40&"."&I40)=$U$11,(H40&"."&I40)=$V$11,(H40&"."&I40)=$W$11),1,0))=1,"RENDAH","-")))) -> MODERAT | K40: 0 | L40: Deskripsi temuan auditor mutu internal tentang indikator yang terkait | M40: Rekomendasi auditor mutu internal berkaitan dengan hasil temuan
C41: 4 | D41: Strategi efektif untuk mencapai tujuan dan disusun berdasarkan analisis yang sistematis dengan menggunakan metoda yang relevan dan terdokumentasi serta pada pelaksanaannya dilakukan pemantauan dan evaluasi dan ditindaklanjuti.
C42: 3 | D42: Strategi efektif untuk mencapai tujuan dan disusun berdasarkan analisis yang sistematis dengan menggunakan metoda yang relevan dan terdokumentasi serta pada pelaksanaannya dilakukan pemantauan dan evaluasi.
C43: 2 | D43: Strategi untuk mencapai tujuan dan disusun berdasarkan analisis yang sistematis dengan menggunakan metoda yang relevan serta terdokumentasi namun belum terbukti efektifitasnya.
C44: 1 | D44: Strategi untuk mencapai tujuan disusun berdasarkan analisis yang kurang sistematis serta tidak menggunakan metoda yang relevan.
C45: 0 | D45: Tidak memiliki strategi untuk mencapai tujuan.
C46: Skor | K46: =IF(OR(ISBLANK(K40),K40<0,K40>4),0,K40) -> 0
...

Sheet Lap AK
B1: LAPORAN ASESMEN KECUKUPAN | H1: PENILAIAN ASESMEN KECUKUPAN
B2: AUDIT MUTU INTERNAL | H2: AUDIT MUTU INTERNAL
B3: ='Kertas Kerja'!A2 -> PROGRAM SARJANA | H3: =B3 -> PROGRAM SARJANA
B5: Penilaian Individual | H5: Nilai Asesmen Kecukupan | L5: =SUM(I13:I87) -> 47.477227 | O5: Peringkat | Q5: =IF(L8="TERPENUHI",IF((IF(L5>=361,"UNGGUL",IF(L5>=301,"BAIK SEKALI",IF(L5>=200,"BAIK","TIDAK TERAKREDITASI"))))="UNGGUL",IF(AND(F30>=3.5,F32>=3.5,F76>=3.5,F77>=3.5),"UNGGUL","BAIK SEKALI"),IF((IF(L5>=361,"UNGGUL",IF(L5>=301,"BAIK SEKALI",IF(L5>=200,"BAIK","TIDAK TERAKREDITASI"))))="BAIK SEKALI",IF(AND(F30>=3,F32>=3,F76>=3,F77>=3),"BAIK SEKALI","BAIK"),IF((IF(L5>=361,"UNGGUL",IF(L5>=301,"BAIK SEKALI",IF(L5>=200,"BAIK","TIDAK TERAKREDITASI"))))="BAIK","BAIK","-"))),"-") -> -
B7: Nama Program Studi | D7: ='Isian Prodi'!C5 -> Prodi A
B8: Nama Auditor Mutu Internal: | H8: Syarat Perlu Terakreditasi | L8: =IF(AND(K24="TERPENUHI",K29="TERPENUHI",K53="TERPENUHI"),"TERPENUHI","TIDAK TERPENUHI") -> TIDAK TERPENUHI
H9: Syarat Perlu Peringkat Unggul | L9: =IF(AND(M30="TERPENUHI",M32="TERPENUHI",M76="TERPENUHI",M77="TERPENUHI"),"TERPENUHI","TIDAK TERPENUHI") -> TIDAK TERPENUHI
B10: Tanggal Penilaian: | H10: Syarat Perlu Peringkat Baik Sekali | L10: =IF(AND(O30="TERPENUHI",O32="TERPENUHI",O76="TERPENUHI",O77="TERPENUHI"),"TERPENUHI","TIDAK TERPENUHI") -> TIDAK TERPENUHI
A12: NO. | B12: NO. | C12: KRITERIA/ELEMEN/INDIKATOR | D12: DESKRIPSI TEMUAN AUDITOR MUTU INTERNAL | E12: REKOMENDASI AUDITOR MUTU INTERNAL | F12: SKOR | H12: BOBOT | I12: SKOR x BOBOT | J12: SYARAT PERLU TERAKREDITASI | L12: SYARAT PERLU PERINGKAT UNGGUL | N12: SYARAT PERLU PERINGKAT BAIK SEKALI
A13: 1 | B13: ='Kertas Kerja'!A8 -> 1 | C13: A. Kondisi Eksternal Konsistensi dengan hasil analisis SWOT dan/atau analisis lain serta rencana pengembangan ke depan. | D13: ='Kertas Kerja'!L8 -> deskripsi test | E13: ='Kertas Kerja'!M8 -> rekomendasi test | F13: ='Kertas Kerja'!K14 -> 3 | H13: 1 | I13: =F13*H13 -> 3 | Q13: 1
A14: 2 | B14: =B13+1 -> 2 | C14: B. Profil Unit Pengelola Program Studi Keserbacakupan informasi dalam profil dan konsistensi antara profil dengan data dan informasi yang disampaikan pada masing-masing kriteria, serta menunjukkan iklim yang kondusif untuk pengembangan dan reputasi sebagai rujukan di bidang keilmuannya. | D14: ='Kertas Kerja'!L16 -> Deskripsi temuan auditor mutu internal tentang indikator yang terkait | E14: ='Kertas Kerja'!M16 -> Rekomendasi auditor mutu internal berkaitan dengan hasil temuan | F14: ='Kertas Kerja'!K22 -> 0 | H14: 1 | I14: =F14*H14 -> 0 | Q14: 2
A15: 3 | B15: =B14+1 -> 3 | C15: C. Kriteria C.1. Visi, Misi, Tujuan dan Strategi C.1.4. Indikator Kinerja Utama Kesesuaian Visi, Misi, Tujuan dan Strategi (VMTS) Unit Pengelola Program Studi (UPPS) terhadap VMTS Perguruan Tinggi (PT) dan visi keilmuan Program Studi (PS) yang dikelolanya. | D15: ='Kertas Kerja'!L24 -> Deskripsi temuan auditor mutu internal tentang indikator yang terkait | E15: ='Kertas Kerja'!M24 -> Rekomendasi auditor mutu internal berkaitan dengan hasil temuan | F15: ='Kertas Kerja'!K30 -> 0 | H15: 0.51111111 | I15: =F15*H15 -> 0 | Q15: 3
A16: 4 | B16: =B15+1 -> 4 | C16: Mekanisme dan keterlibatan pemangku kepentingan dalam penyusunan VMTS UPPS. | D16: ='Kertas Kerja'!L32 -> Deskripsi temuan auditor mutu internal tentang indikator yang terkait | E16: ='Kertas Kerja'!M32 -> Rekomendasi auditor mutu internal berkaitan dengan hasil temuan | F16: ='Kertas Kerja'!K38 -> 0 | H16: 1.0222222 | I16: =F16*H16 -> 0 | Q16: 4
A17: 5 | B17: =B16+1 -> 5 | C17: Strategi pencapaian tujuan disusun berdasarkan analisis yang sistematis, serta pada pelaksanaannya dilakukan pemantauan dan evaluasi yang ditindaklanjuti. | D17: ='Kertas Kerja'!L40 -> Deskripsi temuan auditor mutu internal tentang indikator yang terkait | E17: ='Kertas Kerja'!M40 -> Rekomendasi auditor mutu internal berkaitan dengan hasil temuan | F17: ='Kertas Kerja'!K46 -> 0 | H17: 1.5333333 | I17: =F17*H17 -> 0 | Q17: 5
A18: 6 | B18: =B17+1 -> 6 | C18: C.2. Tata Pamong, Tata Kelola dan Kerjasama C.2.4. Indikator Kinerja Utama C.2.4.a) Sistem Tata Pamong A. Kelengkapan struktur organisasi dan keefektifan penyelenggaraan organisasi. B. Perwujudan good governance dan pemenuhan lima pilar sistem tata pamong, yang mencakup: 1) Kredibel, 2) Transparan, 3) Akuntabel, 4) Bertanggung jawab, 5) Adil. | D18: ='Kertas Kerja'!L48 -> Deskripsi temuan auditor mutu internal tentang indikator yang terkait | E18: ='Kertas Kerja'!M48 -> Rekomendasi auditor mutu internal berkaitan dengan hasil temuan | F18: ='Kertas Kerja'!K60 -> 0 | H18: 0.34074074 | I18: =F18*H18 -> 0 | Q18: 6
A19: 7 | B19: =B18+1 -> 7 | C19: C.2.4.b) Kepemimpinan dan Kemampuan Manajerial A. Komitmen pimpinan UPPS. B. Kapabilitas pimpinan UPPS, mencakup aspek: 1) perencanaan, 2) pengorganisasian, 3) penempatan personel, 4) pelaksanaan, 5) pengendalian dan pengawasan, dan 6) pelaporan yang menjadi dasar tindak lanjut. | D19: ='Kertas Kerja'!L62 -> Deskripsi temuan auditor mutu internal tentang indikator yang terkait | E19: ='Kertas Kerja'!M62 -> Rekomendasi auditor mutu internal berkaitan dengan hasil temuan | F19: ='Kertas Kerja'!K74 -> 0 | H19: 0.34074074 | I19: =F19*H19 -> 0 | Q19: 7
A20: 8 | B20: =B19+1 -> 8 | C20: C.2.4.c) Kerjasama Mutu, manfaat, kepuasan dan keberlanjutan kerjasama pendidikan, penelitian dan PkM yang relevan dengan program studi. UPPS memiliki bukti yang sahih terkait kerjasama yang ada telah memenuhi 3 aspek berikut: 1) memberikan manfaat bagi program studi dalam pemenuhan proses pembelajaran, penelitian, PkM. 2) memberikan peningkatan kinerja tridharma dan fasilitas pendukung program studi. 3) memberikan kepuasan kepada mitra industri dan mitra kerjasama lainnya, serta menjamin keberlanjutan kerjasama dan hasilnya. | D20: ='Kertas Kerja'!L76 -> Deskripsi temuan auditor mutu internal tentang indikator yang terkait | E20: ='Kertas Kerja'!M76 -> Rekomendasi auditor mutu internal berkaitan dengan hasil temuan | F20: ='Kertas Kerja'!K82 -> 0 | H20: 0.68148148 | I20: =F20*H20 -> 0 | Q20: 8
A21: 9 | B21: =B20+1 -> 9 | C21: A. Kerjasama pendidikan, penelitian, dan PkM yang relevan dengan program studi dan dikelola oleh UPPS dalam 3 tahun terakhir. B. Kerjasama tingkat internasional, nasional, wilayah/lokal yang relevan dengan program studi dan dikelola oleh UPPS dalam 3 tahun terakhir. Tabel 1 LKPS | D21: ='Kertas Kerja'!L84 -> Deskripsi temuan auditor mutu internal tentang indikator yang terkait | E21: ='Kertas Kerja'!M84 -> Rekomendasi auditor mutu internal berkaitan dengan hasil temuan | F21: ='Kertas Kerja'!K109 -> 0 | H21: 0.34074074 | I21: =F21*H21 -> 0 | Q21: 9
A22: 10 | B22: =B21+1 -> 10 | C22: C.2.5 Indikator Kinerja Tambahan Pelampauan SN-DIKTI (indikator kinerja tambahan) yang ditetapkan oleh UPPS pada tiap kriteria. | D22: ='Kertas Kerja'!L111 -> Deskripsi temuan auditor mutu internal tentang indikator yang terkait | E22: ='Kertas Kerja'!M111 -> Rekomendasi auditor mutu internal berkaitan dengan hasil temuan | F22: ='Kertas Kerja'!K117 -> 0 | H22: 0.68148148 | I22: =F22*H22 -> 0 | Q22: 10
A23: 11 | B23: =B22+1 -> 11 | C23: C.2.6 Evaluasi Capaian Kinerja Analisis keberhasilan dan/atau ketidakberhasilan pencapaian kinerja UPPS yang telah ditetapkan di tiap kriteria memenuhi 2 aspek sebagai berikut: 1) capaian kinerja diukur dengan metoda yang tepat, dan hasilnya dianalisis serta dievaluasi, dan 2) analisis terhadap capaian kinerja mencakup identifikasi akar masalah, faktor pendukung keberhasilan dan faktor penghambat ketercapaian standard, dan deskripsi singkat tindak lanjut yang akan dilakukan. | D23: ='Kertas Kerja'!L119 -> Deskripsi temuan auditor mutu internal tentang indikator yang terkait | E23: ='Kertas Kerja'!M119 -> Rekomendasi auditor mutu internal berkaitan dengan hasil temuan | F23: ='Kertas Kerja'!K125 -> 0 | H23: 1.0222222 | I23: =F23*H23 -> 0 | Q23: 11
A24: 12 | B24: =B23+1 -> 12 | C24: C.2.7. Penjaminan Mutu Keterlaksanaan Sistem Penjaminan Mutu Internal (akademik dan nonakademik) yang dibuktikan dengan keberadaan 5 aspek: 1) dokumen legal pembentukan unsur pelaksana penjaminan mutu, 2) ketersediaan dokumen mutu: kebijakan SPMI, manual SPMI, standar SPMI, dan formulir SPMI, 3) terlaksananya siklus penjaminan mutu (siklus PPEPP), 4) bukti sahih efektivitas pelaksanaan penjaminan mutu, dan 5) memiliki external benchmarking dalam peningkatan mutu. | D24: ='Kertas Kerja'!L127 -> Deskripsi temuan auditor mutu internal tentang indikator yang terkait | E24: ='Kertas Kerja'!M127 -> Rekomendasi auditor mutu internal berkaitan dengan hasil temuan | F24: ='Kertas Kerja'!K133 -> 0 | H24: 1.362963 | I24: =F24*H24 -> 0 | J24: Skor min. = 2,0 | K24: =IF(F24>=2,"TERPENUHI","TIDAK TERPENUHI") -> TIDAK TERPENUHI | Q24: 12
A25: 13 | B25: =B24+1 -> 13 | C25: C.2.8. Kepuasan Pemangku Kepentingan Pengukuran kepuasan layanan manajemen terhadap para pemangku kepentingan: mahasiswa, dosen, tenaga kependidikan, lulusan, pengguna dan mitra yang memenuhi aspek-aspek berikut: 1) menggunakan instrumen kepuasan yang sahih, andal, mudah digunakan, 2) dilaksanakan secara berkala, serta datanya terekam secara komprehensif, 3) dianalisis dengan metode yang tepat serta bermanfaat untuk pengambilan keputusan, 4) tingkat kepuasan dan umpan balik ditindaklanjuti untuk perbaikan dan peningkatan mutu luaran secara berkala dan tersistem, 5) dilakukan review terhadap pelaksanaan pengukuran kepuasan dosen dan mahasiswa, serta 6) hasilnya dipublikasikan dan mudah diakses oleh dosen dan mahasiswa. | D25: ='Kertas Kerja'!L135 -> Deskripsi temuan auditor mutu internal tentang indikator yang terkait | E25: ='Kertas Kerja'!M135 -> Rekomendasi auditor mutu internal berkaitan dengan hasil temuan | F25: ='Kertas Kerja'!K141 -> 0 | H25: 1.362963 | I25: =F25*H25 -> 0 | Q25: 13
A26: 14 | B26: =B25+1 -> 14 | C26: C.3. Mahasiswa C.3.4. Indikator Kinerja Utama C.3.4.a) Kualitas Input Mahasiswa A. Metoda rekrutmen dan keketatan seleksi. Tabel 2.a LKPS | D26: ='Kertas Kerja'!L143 -> Deskripsi temuan auditor mutu internal tentang indikator yang terkait | E26: ='Kertas Kerja'!M143 -> Rekomendasi auditor mutu internal berkaitan dengan hasil temuan | F26: ='Kertas Kerja'!K157 -> 0 | H26: 4.6 | I26: =F26*H26 -> 0 | Q26: 14
A27: 15 | B27: =B26+1 -> 15 | C27: C.3.4.b) Daya Tarik Program Studi A. Peningkatan animo calon mahasiswa. Tabel 2.a LKPS B. Mahasiswa asing Tabel 2.b LKPS | D27: ='Kertas Kerja'!L159 -> Deskripsi temuan auditor mutu internal tentang indikator yang terkait | E27: ='Kertas Kerja'!M159 -> Rekomendasi auditor mutu internal berkaitan dengan hasil temuan | F27: ='Kertas Kerja'!K173 -> 0 | H27: 3.0666667 | I27: =F27*H27 -> 0 | Q27: 15
A28: 16 | B28: =B27+1 -> 16 | C28: C.3.4.c) Layanan Kemahasiswaan A. Ketersediaan layanan kemahasiswaan di bidang: 1) penalaran, minat dan bakat, 2) kesejahteraan (bimbingan dan konseling, layanan beasiswa, dan layanan kesehatan), dan 3) bimbingan karir dan kewirausahaan. B. Akses dan mutu layanan kemahasiswaan. | D28: ='Kertas Kerja'!L175 -> Deskripsi temuan auditor mutu internal tentang indikator yang terkait | E28: ='Kertas Kerja'!M175 -> Rekomendasi auditor mutu internal berkaitan dengan hasil temuan | F28: ='Kertas Kerja'!K187 -> 0 | H28: 1.5333333 | I28: =F28*H28 -> 0 | Q28: 16
A29: 17 | B29: =B28+1 -> 17 | C29: C.4. Sumber Daya Manusia C.4.4. Indikator Kinerja Utama C.4.4.a) Profil Dosen Kecukupan jumlah DTPS. Tabel 3.a.1) LKPS | D29: ='Kertas Kerja'!L189 -> Deskripsi temuan auditor mutu internal tentang indikator yang terkait | E29: ='Kertas Kerja'!M189 -> Rekomendasi auditor mutu internal berkaitan dengan hasil temuan | F29: ='Kertas Kerja'!K197 -> 0 | H29: 0.74343434 | I29: =F29*H29 -> 0 | J29: Skor min. = 2,0 | K29: =IF(F29>=2,"TERPENUHI","TIDAK TERPENUHI") -> TIDAK TERPENUHI | Q29: 17
A30: 18 | B30: =B29+1 -> 18 | C30: Kualifikasi akademik DTPS. Tabel 3.a.1) LKPS | D30: ='Kertas Kerja'!L199 -> Deskripsi temuan auditor mutu internal tentang indikator yang terkait | E30: ='Kertas Kerja'!M199 -> Rekomendasi auditor mutu internal berkaitan dengan hasil temuan | F30: ='Kertas Kerja'!K203 -> 2 | H30: 0.99124579 | I30: =F30*H30 -> 1.9824916 | L30: Skor min. = 3,5 | M30: =IF(F30>=3.5,"TERPENUHI","TIDAK TERPENUHI") -> TIDAK TERPENUHI | N30: Skor min. = 3,0 | O30: =IF(F30>=3,"TERPENUHI","TIDAK TERPENUHI") -> TIDAK TERPENUHI | Q30: 18
A31: 19 | B31: =B30+1 -> 19 | D31: ='[1]Kertas Kerja'!H204 -> 0 | F31: ='[1]Kertas Kerja'!E209 -> 0 | I31: =F31*H31 -> 0 | Q31: 19
A32: 20 | B32: =B30+1 -> 19 | C32: Jabatan akademik DTPS. Tabel 3.a.1) LKPS | D32: ='Kertas Kerja'!L205 -> Deskripsi temuan auditor mutu internal tentang indikator yang terkait | E32: ='Kertas Kerja'!M205 -> Rekomendasi auditor mutu internal berkaitan dengan hasil temuan | F32: ='Kertas Kerja'!K211 -> 2 | H32: 0.4956229 | I32: =F32*H32 -> 0.99124579 | L32: Skor min. = 3,5 | M32: =IF(F32>=3.5,"TERPENUHI","TIDAK TERPENUHI") -> TIDAK TERPENUHI | N32: Skor min. = 3,0 | O32: =IF(F32>=3,"TERPENUHI","TIDAK TERPENUHI") -> TIDAK TERPENUHI | Q32: 20
A33: 21 | B33: =B32+1 -> 20 | C33: Rasio jumlah mahasiswa program studi terhadap jumlah DTPS. Tabel 2.a LKPS Tabel 3.a.1) LKPS | D33: ='Kertas Kerja'!L219 -> Deskripsi temuan auditor mutu internal tentang indikator yang terkait | E33: ='Kertas Kerja'!M219 -> Rekomendasi auditor mutu internal berkaitan dengan hasil temuan | F33: ='Kertas Kerja'!K226 -> 0 | H33: 0.4956229 | I33: =F33*H33 -> 0 | Q33: 21
A34: 22 | B34: =B33+1 -> 21 | C34: Penugasan DTPS sebagai pembimbing utama tugas akhir mahasiswa. Tabel 3.a.2) LKPS | D34: ='Kertas Kerja'!L228 -> Deskripsi temuan auditor mutu internal tentang indikator yang terkait | E34: ='Kertas Kerja'!M228 -> Rekomendasi auditor mutu internal berkaitan dengan hasil temuan | F34: ='Kertas Kerja'!K232 -> 4 | H34: 0.99124579 | I34: =F34*H34 -> 3.9649832 | Q34: 22
A35: 23 | B35: =B34+1 -> 22 | C35: Ekuivalensi Waktu Mengajar Penuh DTPS. Tabel 3.a.3) LKPS | D35: ='Kertas Kerja'!L234 -> Deskripsi temuan auditor mutu internal tentang indikator yang terkait | E35: ='Kertas Kerja'!M234 -> Rekomendasi auditor mutu internal berkaitan dengan hasil temuan | F35: ='Kertas Kerja'!K236 -> 0 | H35: 0.24781145 | I35: =F35*H35 -> 0 | Q35: 23
A36: 24 | B36: =B35+1 -> 23 | C36: Dosen tidak tetap. Tabel 3.a.4) LKPS | D36: ='Kertas Kerja'!L238 -> Deskripsi temuan auditor mutu internal tentang indikator yang terkait | E36: ='Kertas Kerja'!M238 -> Rekomendasi auditor mutu internal berkaitan dengan hasil temuan | F36: ='Kertas Kerja'!K242 -> 4 | H36: 0.4956229 | I36: =F36*H36 -> 1.9824916 | Q36: 24
A37: 25 | B37: =B36+1 -> 24 | D37: ='[1]Kertas Kerja'!H267 -> 0 | F37: ='[1]Kertas Kerja'!E272 -> 0 | I37: =F37*H37 -> 0 | Q37: 25
A38: 26 | B38: =B36+1 -> 24 | C38: C.4.4.b) Kinerja Dosen Pengakuan/rekognisi atas kepakaran/prestasi/kinerja DTPS. Tabel 3.b.1) LKPS | D38: ='Kertas Kerja'!L244 -> Deskripsi temuan auditor mutu internal tentang indikator yang terkait | E38: ='Kertas Kerja'!M244 -> Rekomendasi auditor mutu internal berkaitan dengan hasil temuan | F38: ='Kertas Kerja'!K248 -> 2 | H38: 0.81101928 | I38: =F38*H38 -> 1.6220386 | Q38: 26
A39: 27 | B39: =B38+1 -> 25 | C39: Kegiatan penelitian DTPS yang relevan dengan bidang program studi dalam 3 tahun terakhir. Tabel 3.b.2) LKPS | D39: ='Kertas Kerja'!L250 -> Deskripsi temuan auditor mutu internal tentang indikator yang terkait | E39: ='Kertas Kerja'!M250 -> Rekomendasi auditor mutu internal berkaitan dengan hasil temuan | F39: ='Kertas Kerja'!K266 -> 0 | H39: 0.81101928 | I39: =F39*H39 -> 0 | Q39: 27
A40: 28 | B40: =B39+1 -> 26 | C40: Kegiatan PkM DTPS yang relevan dengan bidang program studi dalam 3 tahun terakhir. Tabel 3.b.3) LKPS | D40: ='Kertas Kerja'!L268 -> Deskripsi temuan auditor mutu internal tentang indikator yang terkait | E40: ='Kertas Kerja'!M268 -> Rekomendasi auditor mutu internal berkaitan dengan hasil temuan | F40: ='Kertas Kerja'!K284 -> 0 | H40: 0.40550964 | I40: =F40*H40 -> 0 | Q40: 28
A41: 29 | B41: =B40+1 -> 27 | C41: Publikasi ilmiah dengan tema yang relevan dengan bidang program studi yang dihasilkan DTPS dalam 3 tahun terakhir. Tabel 3.b.4) LKPS | D41: ='Kertas Kerja'!L286 -> Deskripsi temuan auditor mutu internal tentang indikator yang terkait | E41: ='Kertas Kerja'!M286 -> Rekomendasi auditor mutu internal berkaitan dengan hasil temuan | F41: ='Kertas Kerja'!K309 -> 0 | H41: 0.81101928 | I41: =F41*H41 -> 0 | Q41: 29
A42: 30 | B42: =B41+1 -> 28 | C42: Artikel karya ilmiah DTPS yang disitasi dalam 3 tahun terakhir. Tabel 3.b.5) LKPS | D42: ='Kertas Kerja'!L311 -> Deskripsi temuan auditor mutu internal tentang indikator yang terkait | E42: ='Kertas Kerja'!M311 -> Rekomendasi auditor mutu internal berkaitan dengan hasil temuan | F42: ='Kertas Kerja'!K316 -> 2 | H42: 0.81101928 | I42: =F42*H42 -> 1.6220386 | Q42: 30
A43: 31 | B43: =B42+1 -> 29 | D43: ='[1]Kertas Kerja'!H349 -> 0 | F43: ='[1]Kertas Kerja'!E354 -> 0 | I43: =F43*H43 -> 0 | Q43: 31
...

Sheet Lap ED
A1: LAPORAN EVALUASI DIRI
A2: ='Isian Prodi'!C5 -> Prodi A
A5: NO. | B5: KRITERIA/ELEMEN/INDIKATOR | C5: EVALUASI DIRI PROGRAM STUDI | D5: IDENTIFIKASI RISIKO | E5: LEVEL RISIKO
A6: 1 | B6: A. Kondisi Eksternal Konsistensi dengan hasil analisis SWOT dan/atau analisis lain serta rencana pengembangan ke depan. | C6: ='Kertas Kerja'!F8 -> Deskripsi dan penjelasan tentang indikator yang terkait | D6: ='Kertas Kerja'!G8 -> Deskripsi identifikasi risiko tentang indikator yang terkait | E6: ='Kertas Kerja'!J8 -> TINGGI | G6: ='Kertas Kerja'!H8 -> C | H6: ='Kertas Kerja'!I8 -> 4
A7: =A6+1 -> 2 | B7: B. Profil Unit Pengelola Program Studi Keserbacakupan informasi dalam profil dan konsistensi antara profil dengan data dan informasi yang disampaikan pada masing-masing kriteria, serta menunjukkan iklim yang kondusif untuk pengembangan dan reputasi sebagai rujukan di bidang keilmuannya. | C7: ='Kertas Kerja'!F16 -> Deskripsi dan penjelasan tentang indikator yang terkait | D7: ='Kertas Kerja'!G16 -> Deskripsi identifikasi risiko tentang indikator yang terkait | E7: ='Kertas Kerja'!J16 -> MODERAT | G7: ='Kertas Kerja'!H16 -> E | H7: ='Kertas Kerja'!I16 -> 1
A8: =A7+1 -> 3 | B8: C. Kriteria C.1. Visi, Misi, Tujuan dan Strategi C.1.4. Indikator Kinerja Utama Kesesuaian Visi, Misi, Tujuan dan Strategi (VMTS) Unit Pengelola Program Studi (UPPS) terhadap VMTS Perguruan Tinggi (PT) dan visi keilmuan Program Studi (PS) yang dikelolanya. | C8: ='Kertas Kerja'!F24 -> Deskripsi dan penjelasan tentang indikator yang terkait | D8: ='Kertas Kerja'!G24 -> Deskripsi identifikasi risiko tentang indikator yang terkait | E8: ='Kertas Kerja'!J24 -> EKSTREM | G8: ='Kertas Kerja'!H24 -> E | H8: ='Kertas Kerja'!I24 -> 4
A9: =A8+1 -> 4 | B9: Mekanisme dan keterlibatan pemangku kepentingan dalam penyusunan VMTS UPPS. | C9: ='Kertas Kerja'!F32 -> Deskripsi dan penjelasan tentang indikator yang terkait | D9: ='Kertas Kerja'!G32 -> Deskripsi identifikasi risiko tentang indikator yang terkait | E9: ='Kertas Kerja'!J32 -> MODERAT | G9: ='Kertas Kerja'!H32 -> E | H9: ='Kertas Kerja'!I32 -> 1
A10: =A9+1 -> 5 | B10: Strategi pencapaian tujuan disusun berdasarkan analisis yang sistematis, serta pada pelaksanaannya dilakukan pemantauan dan evaluasi yang ditindaklanjuti. | C10: ='Kertas Kerja'!F40 -> Deskripsi dan penjelasan tentang indikator yang terkait | D10: ='Kertas Kerja'!G40 -> Deskripsi identifikasi risiko tentang indikator yang terkait | E10: ='Kertas Kerja'!J40 -> MODERAT | G10: ='Kertas Kerja'!H40 -> E | H10: ='Kertas Kerja'!I40 -> 1
A11: =A10+1 -> 6 | B11: C.2. Tata Pamong, Tata Kelola dan Kerjasama C.2.4. Indikator Kinerja Utama C.2.4.a) Sistem Tata Pamong A. Kelengkapan struktur organisasi dan keefektifan penyelenggaraan organisasi. B. Perwujudan good governance dan pemenuhan lima pilar sistem tata pamong, yang mencakup: 1) Kredibel, 2) Transparan, 3) Akuntabel, 4) Bertanggung jawab, 5) Adil. | C11: ='Kertas Kerja'!F48 -> Deskripsi dan penjelasan tentang indikator yang terkait | D11: ='Kertas Kerja'!G48 -> Deskripsi identifikasi risiko tentang indikator yang terkait | E11: ='Kertas Kerja'!J48 -> MODERAT | G11: ='Kertas Kerja'!H48 -> E | H11: ='Kertas Kerja'!I48 -> 1
A12: =A11+1 -> 7 | B12: C.2.4.b) Kepemimpinan dan Kemampuan Manajerial A. Komitmen pimpinan UPPS. B. Kapabilitas pimpinan UPPS, mencakup aspek: 1) perencanaan, 2) pengorganisasian, 3) penempatan personel, 4) pelaksanaan, 5) pengendalian dan pengawasan, dan 6) pelaporan yang menjadi dasar tindak lanjut. | C12: ='Kertas Kerja'!F62 -> Deskripsi dan penjelasan tentang indikator yang terkait | D12: ='Kertas Kerja'!G62 -> Deskripsi identifikasi risiko tentang indikator yang terkait | E12: ='Kertas Kerja'!J62 -> MODERAT | G12: ='Kertas Kerja'!H62 -> E | H12: ='Kertas Kerja'!I62 -> 1
A13: =A12+1 -> 8 | B13: C.2.4.c) Kerjasama Mutu, manfaat, kepuasan dan keberlanjutan kerjasama pendidikan, penelitian dan PkM yang relevan dengan program studi. UPPS memiliki bukti yang sahih terkait kerjasama yang ada telah memenuhi 3 aspek berikut: 1) memberikan manfaat bagi program studi dalam pemenuhan proses pembelajaran, penelitian, PkM. 2) memberikan peningkatan kinerja tridharma dan fasilitas pendukung program studi. 3) memberikan kepuasan kepada mitra industri dan mitra kerjasama lainnya, serta menjamin keberlanjutan kerjasama dan hasilnya. | C13: ='Kertas Kerja'!F76 -> Deskripsi dan penjelasan tentang indikator yang terkait | D13: ='Kertas Kerja'!G76 -> Deskripsi identifikasi risiko tentang indikator yang terkait | E13: ='Kertas Kerja'!J76 -> MODERAT | G13: ='Kertas Kerja'!H76 -> E | H13: ='Kertas Kerja'!I76 -> 1
A14: =A13+1 -> 9 | B14: A. Kerjasama pendidikan, penelitian, dan PkM yang relevan dengan program studi dan dikelola oleh UPPS dalam 3 tahun terakhir. B. Kerjasama tingkat internasional, nasional, wilayah/lokal yang relevan dengan program studi dan dikelola oleh UPPS dalam 3 tahun terakhir. Tabel 1 LKPS | C14: ='Kertas Kerja'!F84 -> Deskripsi dan penjelasan tentang indikator yang terkait | D14: ='Kertas Kerja'!G84 -> Deskripsi identifikasi risiko tentang indikator yang terkait | E14: ='Kertas Kerja'!J84 -> MODERAT | G14: ='Kertas Kerja'!H84 -> E | H14: ='Kertas Kerja'!I84 -> 1
A15: =A14+1 -> 10 | B15: C.2.5 Indikator Kinerja Tambahan Pelampauan SN-DIKTI (indikator kinerja tambahan) yang ditetapkan oleh UPPS pada tiap kriteria. | C15: ='Kertas Kerja'!F111 -> Deskripsi dan penjelasan tentang indikator yang terkait | D15: ='Kertas Kerja'!G111 -> Deskripsi identifikasi risiko tentang indikator yang terkait | E15: ='Kertas Kerja'!J111 -> MODERAT | G15: ='Kertas Kerja'!H111 -> E | H15: ='Kertas Kerja'!I111 -> 1
A16: =A15+1 -> 11 | B16: C.2.6 Evaluasi Capaian Kinerja Analisis keberhasilan dan/atau ketidakberhasilan pencapaian kinerja UPPS yang telah ditetapkan di tiap kriteria memenuhi 2 aspek sebagai berikut: 1) capaian kinerja diukur dengan metoda yang tepat, dan hasilnya dianalisis serta dievaluasi, dan 2) analisis terhadap capaian kinerja mencakup identifikasi akar masalah, faktor pendukung keberhasilan dan faktor penghambat ketercapaian standard, dan deskripsi singkat tindak lanjut yang akan dilakukan. | C16: ='Kertas Kerja'!F119 -> Deskripsi dan penjelasan tentang indikator yang terkait | D16: ='Kertas Kerja'!G119 -> Deskripsi identifikasi risiko tentang indikator yang terkait | E16: ='Kertas Kerja'!J119 -> MODERAT | G16: ='Kertas Kerja'!H119 -> E | H16: ='Kertas Kerja'!I119 -> 1
A17: =A16+1 -> 12 | B17: C.2.7. Penjaminan Mutu Keterlaksanaan Sistem Penjaminan Mutu Internal (akademik dan nonakademik) yang dibuktikan dengan keberadaan 5 aspek: 1) dokumen legal pembentukan unsur pelaksana penjaminan mutu, 2) ketersediaan dokumen mutu: kebijakan SPMI, manual SPMI, standar SPMI, dan formulir SPMI, 3) terlaksananya siklus penjaminan mutu (siklus PPEPP), 4) bukti sahih efektivitas pelaksanaan penjaminan mutu, dan 5) memiliki external benchmarking dalam peningkatan mutu. | C17: ='Kertas Kerja'!F127 -> Deskripsi dan penjelasan tentang indikator yang terkait | D17: ='Kertas Kerja'!G127 -> Deskripsi identifikasi risiko tentang indikator yang terkait | E17: ='Kertas Kerja'!J127 -> MODERAT | G17: ='Kertas Kerja'!H127 -> E | H17: ='Kertas Kerja'!I127 -> 1
A18: =A17+1 -> 13 | B18: C.2.8. Kepuasan Pemangku Kepentingan Pengukuran kepuasan layanan manajemen terhadap para pemangku kepentingan: mahasiswa, dosen, tenaga kependidikan, lulusan, pengguna dan mitra yang memenuhi aspek-aspek berikut: 1) menggunakan instrumen kepuasan yang sahih, andal, mudah digunakan, 2) dilaksanakan secara berkala, serta datanya terekam secara komprehensif, 3) dianalisis dengan metode yang tepat serta bermanfaat untuk pengambilan keputusan, 4) tingkat kepuasan dan umpan balik ditindaklanjuti untuk perbaikan dan peningkatan mutu luaran secara berkala dan tersistem, 5) dilakukan review terhadap pelaksanaan pengukuran kepuasan dosen dan mahasiswa, serta 6) hasilnya dipublikasikan dan mudah diakses oleh dosen dan mahasiswa. | C18: ='Kertas Kerja'!F135 -> Deskripsi dan penjelasan tentang indikator yang terkait | D18: ='Kertas Kerja'!G135 -> Deskripsi identifikasi risiko tentang indikator yang terkait | E18: ='Kertas Kerja'!J135 -> MODERAT | G18: ='Kertas Kerja'!H135 -> E | H18: ='Kertas Kerja'!I135 -> 1
A19: =A18+1 -> 14 | B19: C.3. Mahasiswa C.3.4. Indikator Kinerja Utama C.3.4.a) Kualitas Input Mahasiswa A. Metoda rekrutmen dan keketatan seleksi. Tabel 2.a LKPS | C19: ='Kertas Kerja'!F143 -> Deskripsi dan penjelasan tentang indikator yang terkait | D19: ='Kertas Kerja'!G143 -> Deskripsi identifikasi risiko tentang indikator yang terkait | E19: ='Kertas Kerja'!J143 -> MODERAT | G19: ='Kertas Kerja'!H143 -> E | H19: ='Kertas Kerja'!I143 -> 1
A20: =A19+1 -> 15 | B20: C.3.4.b) Daya Tarik Program Studi A. Peningkatan animo calon mahasiswa. Tabel 2.a LKPS B. Mahasiswa asing Tabel 2.b LKPS | C20: ='Kertas Kerja'!F159 -> Deskripsi dan penjelasan tentang indikator yang terkait | D20: ='Kertas Kerja'!G159 -> Deskripsi identifikasi risiko tentang indikator yang terkait | E20: ='Kertas Kerja'!J159 -> MODERAT | G20: ='Kertas Kerja'!H159 -> E | H20: ='Kertas Kerja'!I159 -> 1
A21: =A20+1 -> 16 | B21: C.3.4.c) Layanan Kemahasiswaan A. Ketersediaan layanan kemahasiswaan di bidang: 1) penalaran, minat dan bakat, 2) kesejahteraan (bimbingan dan konseling, layanan beasiswa, dan layanan kesehatan), dan 3) bimbingan karir dan kewirausahaan. B. Akses dan mutu layanan kemahasiswaan. | C21: ='Kertas Kerja'!F175 -> Deskripsi dan penjelasan tentang indikator yang terkait | D21: ='Kertas Kerja'!G175 -> Deskripsi identifikasi risiko tentang indikator yang terkait | E21: ='Kertas Kerja'!J175 -> MODERAT | G21: ='Kertas Kerja'!H175 -> E | H21: ='Kertas Kerja'!I175 -> 1
A22: =A21+1 -> 17 | B22: C.4. Sumber Daya Manusia C.4.4. Indikator Kinerja Utama C.4.4.a) Profil Dosen Kecukupan jumlah DTPS. Tabel 3.a.1) LKPS | C22: ='Kertas Kerja'!F189 -> Deskripsi dan penjelasan tentang indikator yang terkait | D22: ='Kertas Kerja'!G189 -> Deskripsi identifikasi risiko tentang indikator yang terkait | E22: ='Kertas Kerja'!J189 -> TINGGI | G22: ='Kertas Kerja'!H189 -> C | H22: ='Kertas Kerja'!I189 -> 3
A23: =A22+1 -> 18 | B23: Kualifikasi akademik DTPS. Tabel 3.a.1) LKPS | C23: ='Kertas Kerja'!F199 -> Deskripsi dan penjelasan tentang indikator yang terkait | D23: ='Kertas Kerja'!G199 -> Deskripsi identifikasi risiko tentang indikator yang terkait | E23: ='Kertas Kerja'!J199 -> RENDAH | G23: ='Kertas Kerja'!H199 -> A | H23: ='Kertas Kerja'!I199 -> 1
A25: =A23+1 -> 19 | B25: Jabatan akademik DTPS. Tabel 3.a.1) LKPS | C25: ='Kertas Kerja'!F205 -> Deskripsi dan penjelasan tentang indikator yang terkait | D25: ='Kertas Kerja'!G205 -> Deskripsi identifikasi risiko tentang indikator yang terkait | E25: ='Kertas Kerja'!J205 -> RENDAH | G25: ='Kertas Kerja'!H205 -> A | H25: ='Kertas Kerja'!I205 -> 1
A26: =A25+1 -> 20 | B26: Rasio jumlah mahasiswa program studi terhadap jumlah DTPS. Tabel 2.a LKPS Tabel 3.a.1) LKPS | C26: ='Kertas Kerja'!F219 -> Deskripsi dan penjelasan tentang indikator yang terkait | D26: ='Kertas Kerja'!G219 -> Deskripsi identifikasi risiko tentang indikator yang terkait | E26: ='Kertas Kerja'!J219 -> RENDAH | G26: ='Kertas Kerja'!H219 -> A | H26: ='Kertas Kerja'!I219 -> 1
A27: =A26+1 -> 21 | B27: Penugasan DTPS sebagai pembimbing utama tugas akhir mahasiswa. Tabel 3.a.2) LKPS | C27: ='Kertas Kerja'!F228 -> Deskripsi dan penjelasan tentang indikator yang terkait | D27: ='Kertas Kerja'!G228 -> Deskripsi identifikasi risiko tentang indikator yang terkait | E27: ='Kertas Kerja'!J228 -> RENDAH | G27: ='Kertas Kerja'!H228 -> A | H27: ='Kertas Kerja'!I228 -> 1
A28: =A27+1 -> 22 | B28: Ekuivalensi Waktu Mengajar Penuh DTPS. Tabel 3.a.3) LKPS | C28: ='Kertas Kerja'!F234 -> Deskripsi dan penjelasan tentang indikator yang terkait | D28: ='Kertas Kerja'!G234 -> Deskripsi identifikasi risiko tentang indikator yang terkait | E28: ='Kertas Kerja'!J234 -> RENDAH | G28: ='Kertas Kerja'!H234 -> A | H28: ='Kertas Kerja'!I234 -> 1
A29: =A28+1 -> 23 | B29: Dosen tidak tetap. Tabel 3.a.4) LKPS | C29: ='Kertas Kerja'!F238 -> Deskripsi dan penjelasan tentang indikator yang terkait | D29: ='Kertas Kerja'!G238 -> Deskripsi identifikasi risiko tentang indikator yang terkait | E29: ='Kertas Kerja'!J238 -> RENDAH | G29: ='Kertas Kerja'!H238 -> C | H29: ='Kertas Kerja'!I238 -> 1
A31: =A29+1 -> 24 | B31: C.4.4.b) Kinerja Dosen Pengakuan/rekognisi atas kepakaran/prestasi/kinerja DTPS. Tabel 3.b.1) LKPS | C31: ='Kertas Kerja'!F244 -> Deskripsi dan penjelasan tentang indikator yang terkait | D31: ='Kertas Kerja'!G244 -> Deskripsi identifikasi risiko tentang indikator yang terkait | E31: ='Kertas Kerja'!J244 -> RENDAH | G31: ='Kertas Kerja'!H244 -> C | H31: ='Kertas Kerja'!I244 -> 1
A32: =A31+1 -> 25 | B32: Kegiatan penelitian DTPS yang relevan dengan bidang program studi dalam 3 tahun terakhir. Tabel 3.b.2) LKPS | C32: ='Kertas Kerja'!F250 -> Deskripsi dan penjelasan tentang indikator yang terkait | D32: ='Kertas Kerja'!G250 -> Deskripsi identifikasi risiko tentang indikator yang terkait | E32: ='Kertas Kerja'!J250 -> RENDAH | G32: ='Kertas Kerja'!H250 -> C | H32: ='Kertas Kerja'!I250 -> 1
A33: =A32+1 -> 26 | B33: Kegiatan PkM DTPS yang relevan dengan bidang program studi dalam 3 tahun terakhir. Tabel 3.b.3) LKPS | C33: ='Kertas Kerja'!F268 -> Deskripsi dan penjelasan tentang indikator yang terkait | D33: ='Kertas Kerja'!G268 -> Deskripsi identifikasi risiko tentang indikator yang terkait | E33: ='Kertas Kerja'!J268 -> RENDAH | G33: ='Kertas Kerja'!H268 -> C | H33: ='Kertas Kerja'!I268 -> 1
A34: =A33+1 -> 27 | B34: Publikasi ilmiah dengan tema yang relevan dengan bidang program studi yang dihasilkan DTPS dalam 3 tahun terakhir. Tabel 3.b.4) LKPS | C34: ='Kertas Kerja'!F286 -> Deskripsi dan penjelasan tentang indikator yang terkait | D34: ='Kertas Kerja'!G286 -> Deskripsi identifikasi risiko tentang indikator yang terkait | E34: ='Kertas Kerja'!J286 -> RENDAH | G34: ='Kertas Kerja'!H286 -> C | H34: ='Kertas Kerja'!I286 -> 1
A35: =A34+1 -> 28 | B35: Artikel karya ilmiah DTPS yang disitasi dalam 3 tahun terakhir. Tabel 3.b.5) LKPS | C35: ='Kertas Kerja'!F311 -> Deskripsi dan penjelasan tentang indikator yang terkait | D35: ='Kertas Kerja'!G311 -> Deskripsi identifikasi risiko tentang indikator yang terkait | E35: ='Kertas Kerja'!J311 -> RENDAH | G35: ='Kertas Kerja'!H311 -> C | H35: ='Kertas Kerja'!I311 -> 1
A37: =A35+1 -> 29 | B37: Luaran penelitian dan PkM yang dihasilkan DTPS dalam 3 tahun terakhir. Tabel 3.b.7) LKPS | C37: ='Kertas Kerja'!F318 -> Deskripsi dan penjelasan tentang indikator yang terkait | D37: ='Kertas Kerja'!G318 -> Deskripsi identifikasi risiko tentang indikator yang terkait | E37: ='Kertas Kerja'!J318 -> RENDAH | G37: ='Kertas Kerja'!H318 -> C | H37: ='Kertas Kerja'!I318 -> 1
A38: =A37+1 -> 30 | B38: C.4.4.c) Pengembangan Dosen Upaya pengembangan dosen. | C38: ='Kertas Kerja'!F328 -> Deskripsi dan penjelasan tentang indikator yang terkait | D38: ='Kertas Kerja'!G328 -> Deskripsi identifikasi risiko tentang indikator yang terkait | E38: ='Kertas Kerja'!J328 -> RENDAH | G38: ='Kertas Kerja'!H328 -> C | H38: ='Kertas Kerja'!I328 -> 1
A39: =A38+1 -> 31 | B39: C.4.4.d) Tenaga Kependidikan A. Kualifikasi dan kecukupan tenaga kependidikan berdasarkan jenis pekerjaannya (administrasi, pustakawan, teknisi, dll.) B. Kualifikasi dan kecukupan laboran untuk mendukung proses pembelajaran sesuai dengan kebutuhan program studi. | C39: ='Kertas Kerja'!F337 -> Deskripsi dan penjelasan tentang indikator yang terkait | D39: ='Kertas Kerja'!G337 -> Deskripsi identifikasi risiko tentang indikator yang terkait | E39: ='Kertas Kerja'!J337 -> RENDAH | G39: ='Kertas Kerja'!H337 -> C | H39: ='Kertas Kerja'!I337 -> 1
A40: =A39+1 -> 32 | B40: C.5. Keuangan, Sarana dan Prasarana C.5.4. Indikator Kinerja Utama C.5.4.a) Keuangan Biaya operasional pendidikan. Tabel 4 LKPS | C40: ='Kertas Kerja'!F375 -> Deskripsi dan penjelasan tentang indikator yang terkait | D40: ='Kertas Kerja'!G375 -> Deskripsi identifikasi risiko tentang indikator yang terkait | E40: ='Kertas Kerja'!J375 -> RENDAH | G40: ='Kertas Kerja'!H375 -> C | H40: ='Kertas Kerja'!I375 -> 1
A41: =A40+1 -> 33 | B41: Dana penelitian DTPS. Tabel 4 LKPS | C41: ='Kertas Kerja'!F381 -> Deskripsi dan penjelasan tentang indikator yang terkait | D41: ='Kertas Kerja'!G381 -> Deskripsi identifikasi risiko tentang indikator yang terkait | E41: ='Kertas Kerja'!J381 -> RENDAH | G41: ='Kertas Kerja'!H381 -> C | H41: ='Kertas Kerja'!I381 -> 1
A42: =A41+1 -> 34 | B42: Dana pengabdian kepada masyarakat DTPS. Tabel 4 LKPS | C42: ='Kertas Kerja'!F387 -> Deskripsi dan penjelasan tentang indikator yang terkait | D42: ='Kertas Kerja'!G387 -> Deskripsi identifikasi risiko tentang indikator yang terkait | E42: ='Kertas Kerja'!J387 -> RENDAH | G42: ='Kertas Kerja'!H387 -> C | H42: ='Kertas Kerja'!I387 -> 1
A43: =A42+1 -> 35 | B43: Realisasi investasi (SDM, sarana dan prasarana) yang mendukung penyelenggaraan tridharma. | C43: ='Kertas Kerja'!F393 -> Deskripsi dan penjelasan tentang indikator yang terkait | D43: ='Kertas Kerja'!G393 -> Deskripsi identifikasi risiko tentang indikator yang terkait | E43: ='Kertas Kerja'!J393 -> RENDAH | G43: ='Kertas Kerja'!H393 -> C | H43: ='Kertas Kerja'!I393 -> 1
A44: =A43+1 -> 36 | B44: Kecukupan dana untuk menjamin pencapaian capaian pembelajaran. | C44: ='Kertas Kerja'!F402 -> Deskripsi dan penjelasan tentang indikator yang terkait | D44: ='Kertas Kerja'!G402 -> Deskripsi identifikasi risiko tentang indikator yang terkait | E44: ='Kertas Kerja'!J402 -> RENDAH | G44: ='Kertas Kerja'!H402 -> C | H44: ='Kertas Kerja'!I402 -> 1
A45: =A44+1 -> 37 | B45: C.5.4.b) Sarana dan Prasarana Kecukupan, aksesibilitas dan mutu sarana dan prasarana untuk menjamin pencapaian capaian pembelajaran dan meningkatkan suasana akademik. | C45: ='Kertas Kerja'!F410 -> Deskripsi dan penjelasan tentang indikator yang terkait | D45: ='Kertas Kerja'!G410 -> Deskripsi identifikasi risiko tentang indikator yang terkait | E45: ='Kertas Kerja'!J410 -> RENDAH | G45: ='Kertas Kerja'!H410 -> C | H45: ='Kertas Kerja'!I410 -> 1
...

Sheet Peta Risiko
A1: PETA RISIKO
A2: ='Isian Prodi'!C5 -> Prodi A
B4: TINGKAT KEMUNGKINAN | C4: Sangat Besar | D4: E | E4: =C15&" "&C16&" "&C17&" "&C18&" "&C19&" "&C20&" "&C21&" "&C22&" "&C23&" "&C24&" "&C25&" "&C26&" "&C27&" "&C28&" "&C29&" "&C30&" "&C31&" "&C32&" "&C33&" "&C34&" "&C35&" "&C36&" "&C37&" "&C38&" "&C39&" "&C40&" "&C41&" "&C42&" "&C43&" "&C44&" "&C45&" "&C46&" "&C47&" "&C48&" "&C49&" "&C50&" "&C51&" "&C52&" "&C53&" "&C54&" "&C55&" "&C56&" "&C57&" "&C58&" "&C59&" "&C60&" "&C61&" "&C62&" "&C63&" "&C64&" "&C65&" "&C66&" "&C67&" "&C68&" "&C69&" "&C70&" "&C71&" "&C72&" "&C73&" "&C74&" "&C75&" "&C76&" "&C77&" "&C78&" "&C79&" "&C80&" "&C81&" "&C82&" "&C83 -> 2 4 5 6 7 8 9 10 11 12 13 14 15 16 | F4: =D15&" "&D16&" "&D17&" "&D18&" "&D19&" "&D20&" "&D21&" "&D22&" "&D23&" "&D24&" "&D25&" "&D26&" "&D27&" "&D28&" "&D29&" "&D30&" "&D31&" "&D32&" "&D33&" "&D34&" "&D35&" "&D36&" "&D37&" "&D38&" "&D39&" "&D40&" "&D41&" "&D42&" "&D43&" "&D44&" "&D45&" "&D46&" "&D47&" "&D48&" "&D49&" "&D50&" "&D51&" "&D52&" "&D53&" "&D54&" "&D55&" "&D56&" "&D57&" "&D58&" "&D59&" "&D60&" "&D61&" "&D62&" "&D63&" "&D64&" "&D65&" "&D66&" "&D67&" "&D68&" "&D69&" "&D70&" "&D71&" "&D72&" "&D73&" "&D74&" "&D75&" "&D76&" "&D77&" "&D78&" "&D79&" "&D80&" "&D81&" "&D82&" "&D83 | G4: =E15&" "&E16&" "&E17&" "&E18&" "&E19&" "&E20&" "&E21&" "&E22&" "&E23&" "&E24&" "&E25&" "&E26&" "&E27&" "&E28&" "&E29&" "&E30&" "&E31&" "&E32&" "&E33&" "&E34&" "&E35&" "&E36&" "&E37&" "&E38&" "&E39&" "&E40&" "&E41&" "&E42&" "&E43&" "&E44&" "&E45&" "&E46&" "&E47&" "&E48&" "&E49&" "&E50&" "&E51&" "&E52&" "&E53&" "&E54&" "&E55&" "&E56&" "&E57&" "&E58&" "&E59&" "&E60&" "&E61&" "&E62&" "&E63&" "&E64&" "&E65&" "&E66&" "&E67&" "&E68&" "&E69&" "&E70&" "&E71&" "&E72&" "&E73&" "&E74&" "&E75&" "&E76&" "&E77&" "&E78&" "&E79&" "&E80&" "&E81&" "&E82&" "&E83 | H4: =F15&" "&F16&" "&F17&" "&F18&" "&F19&" "&F20&" "&F21&" "&F22&" "&F23&" "&F24&" "&F25&" "&F26&" "&F27&" "&F28&" "&F29&" "&F30&" "&F31&" "&F32&" "&F33&" "&F34&" "&F35&" "&F36&" "&F37&" "&F38&" "&F39&" "&F40&" "&F41&" "&F42&" "&F43&" "&F44&" "&F45&" "&F46&" "&F47&" "&F48&" "&F49&" "&F50&" "&F51&" "&F52&" "&F53&" "&F54&" "&F55&" "&F56&" "&F57&" "&F58&" "&F59&" "&F60&" "&F61&" "&F62&" "&F63&" "&F64&" "&F65&" "&F66&" "&F67&" "&F68&" "&F69&" "&F70&" "&F71&" "&F72&" "&F73&" "&F74&" "&F75&" "&F76&" "&F77&" "&F78&" "&F79&" "&F80&" "&F81&" "&F82&" "&F83 -> 3 | I4: =G15&" "&G16&" "&G17&" "&G18&" "&G19&" "&G20&" "&G21&" "&G22&" "&G23&" "&G24&" "&G25&" "&G26&" "&G27&" "&G28&" "&G29&" "&G30&" "&G31&" "&G32&" "&G33&" "&G34&" "&G35&" "&G36&" "&G37&" "&G38&" "&G39&" "&G40&" "&G41&" "&G42&" "&G43&" "&G44&" "&G45&" "&G46&" "&G47&" "&G48&" "&G49&" "&G50&" "&G51&" "&G52&" "&G53&" "&G54&" "&G55&" "&G56&" "&G57&" "&G58&" "&G59&" "&G60&" "&G61&" "&G62&" "&G63&" "&G64&" "&G65&" "&G66&" "&G67&" "&G68&" "&G69&" "&G70&" "&G71&" "&G72&" "&G73&" "&G74&" "&G75&" "&G76&" "&G77&" "&G78&" "&G79&" "&G80&" "&G81&" "&G82&" "&G83
C5: Besar | D5: D | E5: =H15&" "&H16&" "&H17&" "&H18&" "&H19&" "&H20&" "&H21&" "&H22&" "&H23&" "&H24&" "&H25&" "&H26&" "&H27&" "&H28&" "&H29&" "&H30&" "&H31&" "&H32&" "&H33&" "&H34&" "&H35&" "&H36&" "&H37&" "&H38&" "&H39&" "&H40&" "&H41&" "&H42&" "&H43&" "&H44&" "&H45&" "&H46&" "&H47&" "&H48&" "&H49&" "&H50&" "&H51&" "&H52&" "&H53&" "&H54&" "&H55&" "&H56&" "&H57&" "&H58&" "&H59&" "&H60&" "&H61&" "&H62&" "&H63&" "&H64&" "&H65&" "&H66&" "&H67&" "&H68&" "&H69&" "&H70&" "&H71&" "&H72&" "&H73&" "&H74&" "&H75&" "&H76&" "&H77&" "&H78&" "&H79&" "&H80&" "&H81&" "&H82&" "&H83 | F5: =I15&" "&I16&" "&I17&" "&I18&" "&I19&" "&I20&" "&I21&" "&I22&" "&I23&" "&I24&" "&I25&" "&I26&" "&I27&" "&I28&" "&I29&" "&I30&" "&I31&" "&I32&" "&I33&" "&I34&" "&I35&" "&I36&" "&I37&" "&I38&" "&I39&" "&I40&" "&I41&" "&I42&" "&I43&" "&I44&" "&I45&" "&I46&" "&I47&" "&I48&" "&I49&" "&I50&" "&I51&" "&I52&" "&I53&" "&I54&" "&I55&" "&I56&" "&I57&" "&I58&" "&I59&" "&I60&" "&I61&" "&I62&" "&I63&" "&I64&" "&I65&" "&I66&" "&I67&" "&I68&" "&I69&" "&I70&" "&I71&" "&I72&" "&I73&" "&I74&" "&I75&" "&I76&" "&I77&" "&I78&" "&I79&" "&I80&" "&I81&" "&I82&" "&I83 | G5: =J15&" "&J16&" "&J17&" "&J18&" "&J19&" "&J20&" "&J21&" "&J22&" "&J23&" "&J24&" "&J25&" "&J26&" "&J27&" "&J28&" "&J29&" "&J30&" "&J31&" "&J32&" "&J33&" "&J34&" "&J35&" "&J36&" "&J37&" "&J38&" "&J39&" "&J40&" "&J41&" "&J42&" "&J43&" "&J44&" "&J45&" "&J46&" "&J47&" "&J48&" "&J49&" "&J50&" "&J51&" "&J52&" "&J53&" "&J54&" "&J55&" "&J56&" "&J57&" "&J58&" "&J59&" "&J60&" "&J61&" "&J62&" "&J63&" "&J64&" "&J65&" "&J66&" "&J67&" "&J68&" "&J69&" "&J70&" "&J71&" "&J72&" "&J73&" "&J74&" "&J75&" "&J76&" "&J77&" "&J78&" "&J79&" "&J80&" "&J81&" "&J82&" "&J83 | H5: =K15&" "&K16&" "&K17&" "&K18&" "&K19&" "&K20&" "&K21&" "&K22&" "&K23&" "&K24&" "&K25&" "&K26&" "&K27&" "&K28&" "&K29&" "&K30&" "&K31&" "&K32&" "&K33&" "&K34&" "&K35&" "&K36&" "&K37&" "&K38&" "&K39&" "&K40&" "&K41&" "&K42&" "&K43&" "&K44&" "&K45&" "&K46&" "&K47&" "&K48&" "&K49&" "&K50&" "&K51&" "&K52&" "&K53&" "&K54&" "&K55&" "&K56&" "&K57&" "&K58&" "&K59&" "&K60&" "&K61&" "&K62&" "&K63&" "&K64&" "&K65&" "&K66&" "&K67&" "&K68&" "&K69&" "&K70&" "&K71&" "&K72&" "&K73&" "&K74&" "&K75&" "&K76&" "&K77&" "&K78&" "&K79&" "&K80&" "&K81&" "&K82&" "&K83 | I5: =L15&" "&L16&" "&L17&" "&L18&" "&L19&" "&L20&" "&L21&" "&L22&" "&L23&" "&L24&" "&L25&" "&L26&" "&L27&" "&L28&" "&L29&" "&L30&" "&L31&" "&L32&" "&L33&" "&L34&" "&L35&" "&L36&" "&L37&" "&L38&" "&L39&" "&L40&" "&L41&" "&L42&" "&L43&" "&L44&" "&L45&" "&L46&" "&L47&" "&L48&" "&L49&" "&L50&" "&L51&" "&L52&" "&L53&" "&L54&" "&L55&" "&L56&" "&L57&" "&L58&" "&L59&" "&L60&" "&L61&" "&L62&" "&L63&" "&L64&" "&L65&" "&L66&" "&L67&" "&L68&" "&L69&" "&L70&" "&L71&" "&L72&" "&L73&" "&L74&" "&L75&" "&L76&" "&L77&" "&L78&" "&L79&" "&L80&" "&L81&" "&L82&" "&L83
